Workbook

Sheet วิธีใช้โปรแกรม (ง่ายๆ)
A1: วิธีใช้งานไฟล์นี้เวอร์ : ชั่นคอมพิวเตอร์ 💻
A2: 1. กดที่เมนู ไฟล์ (File) ทำสำเนา (Make a copy)
A3: 2. ทำสำเนา (Make a copy)
A4: (จากนั้นไฟล์จะไปอยู่ใน Google Drive ของคุณ สามารถแก้ไขได้ทันที)
A7: วิธีใช้งานไฟล์นี้ : เวอร์ชั่นมือถือ 📱
A8: 1. กดปุ่ม … มุมขวาบนของไฟล์ 2. เลือก Share & export 3. กด Make a copy เพื่อคัดลอก (จากนั้นไฟล์จะไปอยู่ใน Google Drive ของคุณ สามารถแก้ไขได้ทันที)
A10: (มือถือให้เปิดลิงก์ผ่าน Browser เช่น Safari หรือ Chrome ไม่ใช่แอป LINE / Facebook)
B12: License - Baygeta
B13: สามารถคัดลอก แก้ไข และแจกจ่ายไฟล์นี้ได้อิสระ ห้ามนำไปขายหรือใช้เพื่อการค้า

Sheet เริ่มต้นอ่านก่อน
A1: เข้าใจการเล่นสายธรรมชาติลงโทษ | M1: Old School กุคิดว่าอยู่ยุค 2000
A2: ผมกล้าการันตีว่าถ้าคุณเล่นตามโปรแกรมที่ผมจัดไว้ให้โดยมีเวลาประมาณ 3-4 วัน/สัปดาห์ จะทำให้คุณเปลี่ยนแปลงรูปร่างจนคนใกล้ตัวที่ไม่ได้เจอนานๆทักแน่นอนในระยะเวลา 3-4 เดือน
A3: แต่ถ้าอยากจะหุ่นแบบ Influencer ใน IG ที่เขามีการใช้สารกระตุ้นและทุ่มเท่ไปถึง 5-10+ ปี ในเวลา 3-4 เดือนผมบอกเลยว่าทำไม่ได้
A4: แต่ถ้าคุณเล่นโดย ไม่หลงทาง และเข้าใจหลักพื้นฐานที่ถูกต้อง การพัฒนารูปร่างก็ยังเกิดขึ้นได้ มี 7 ข้อหลักที่อยากให้ทุกคนเข้าใจ
B5: มีงานทดลองแบ่งคน 4 กลุ่ม 10 สัปดาห์
B6: กลุ่ม | C6: ออกกำลังกาย | D6: ใช้ยา | E6: ผลลัพธ์ | G6: ถ้าคุณอยู่ใน กลุ่ม C ก็ไม่ต้องแปลกใจ
B7: A | C7: ✓ | D7: ✓ | E7: โตมากที่สุด | G7: ลองหาช่องที่สรุปเรื่องสารกระตุ้นในการสร้างกล้ามเนื้อ ดูแล้วจะเข้าใจว่ามันช่วยได้มากแค่ไหน ในโลกความเป็นจริง การออกมายอมรับว่า ไม่ได้เป็นสายธรรมชาติ ยังเป็นเรื่องที่หลายคนไม่กล้าพูดตรง ๆ เหตุผลคือ นักกีฬาบางรายการถ้ายอมรับว่าใช้สารกระตุ้น อาจถูก ตัดสิทธิ์การแข่งขันถาวร ในรายการนั้นได้ (ยกเว้นบางรายการที่เปิดให้ใช้ได้อย่างเต็มที่) ทั้งนี้ตัวโปรแกรมที่ผมออกแบบมา ยึดหลักสำหรับสายธรรมชาติเป็นหลัก (ประสบการณ์ตรงลองผิดลองถูกมา 15+ปี) ปริมาณการฝึก ความถี่ และการเพิ่มน้ำหนัก ถูกวางให้เหมาะกับคนที่ไม่ได้ใช้สารกระตุ้น เพื่อให้ฟื้นตัวได้และพัฒนาได้ต่อเนื่อง
B8: B | C8: ✗ | D8: ✓ | E8: กล้ามเพิ่ม
B9: C | C9: ✓ | D9: ✗ | E9: โตเล็กน้อย
B10: D | C10: ✗ | D10: ✗ | E10: ไม่โต
A12: 1.เรื่องกิน
A13: ถ้าเป็นส่วนตัวผมเองที่ทำอยู่ทุกวันนี้เกิน 7ปี+ ท่องไว้เลย โปรตีนประมาณ 1.7-2.2 g ต่อ น้ำหนักตัว 1 กก. ก็พอในหน้า การกิน (ข้างล่างคำนวณระเอียดไว้เรียบร้อย)
A14: ส่วนตัวผมก็มนุษย์ทั่วไปมีกิเลศกินเละเทะบ้าง แต่จำไว้ว่าเมื่อไหร่ที่คุณกินโปรตีนถึงในวันนั้นคุณจะกินอะไรก็ได้พยายามอย่าให้มันแปลรูป
A15: แน่นอนถ้าคุณเป็นคนผอมแห้งอยู่แล้วการเพิ่มแคลก็ไม่เสียหาย เพิ่มแคลอรี่ทีละ 200–400 kcal ไม่ต้อง bulk บ้าพลังเดียวเลยป้ายลดลงยากอีก (ส่วนถ้าใครที่น้ำหนักเยอะก็ให้ทำตรงกันข้ามแทน)
A16: ไม่ว่าจะข้าวที่บ้านที่ทำเองหรือคนที่บ้านทำ แนะนำให้ทำอาหารที่ไม่แปลรูป
A17: ส่วนผักผลไม้เห็นก็ซื้อมาให้ง่ายเหมือนมีโปรปีใหม่หรือเกมราคาลด แช่ไว้ในตู้เย็นนั้นแหละครับ กินพอให้ได้มากที่สุด (แนะนำฝรั่งCสูงมาก,กล้วยโพแทสเซี่ยมสูงแก้ตะคิว)
B19: ไม่แปรรูป | C19: แปรรูป | E19: ระดับโปรตีน | F19: g/Kg นน.ตัว | G19: ผลลัพธ์
B20: อกไก่สด | C20: ไส้กรอก | E20: ต่ำเกินไป | F20: ต่ำกว่า 0.8 g | G20: มาตราฐาน ที่ควรได้รับ | I20: ผักบุ้ง,กล้วย | J20: โพแทสเซียมสูง
B21: น่องไก่สด | C21: แฮม
B22: หมูสด | C22: เบคอน | I22: สับปะรด,มะละกอ | J22: มีเอนไซม์ช่วยย่อยโปรตีน
B23: เนื้อวัวสด | C23: ลูกชิ้นเนื้อ | E23: เกณฑ์มาตรฐาน | F23: 1.0–1.5 g | G23: พัฒนาได้
B24: ปลาสด | C24: ปลากระป๋อง | I24: คะน้า,ฝรั่ง,กีวี่ | J24: วิตามิน C สูง
B25: ไข่ไก่ | C25: ไข่หวาน
B26: กุ้งสด | C26: ปูอัด | E26: พัฒนาได้ดี | F26: 1.7–2.2 g | G26: พัฒนาได้ดี คุมน้ำหนักง่าย | I26: แอลม่อน เมล็ดทานตะวัน | J26: ไขมันดีสูง
B27: เต้าหู้ | C27: แป้งทอด
B28: มันฝรั่ง | C28: เฟรนช์ฟรายส์
A30: 2.ชั่งน้ำหนักทุกวัน
A31: ฟังแล้วอาจจะตลกชั่งแบบทุกอาทิตย์ไม่ได้หรอ จริงๆมันได้หมดแหละส่วนตัวการชั่งทุกวันมันมีน้ำหนักที่คาดเคลื่อน(น้ำ,อาหาร)อยู่แล้ว 2-3 กิโล
A32: แต่การชั่งทุกวันจะทำให้เพื่อนๆไม่หลงทางเหมือนเดินป่าที่มีเข็มทิศตลอด ว่าเรานั้นกำลังขึ้นเหนือหรือลงใต้ ซึ่งต่อให้ผมออกกำลังกายมา 15ปี+ ทุกวันนี้ผมก็ชั่งทุกเช้าก่อนจะกินกาแฟ
A33: (แนะนำให้หาเวลาชั่งเดิมทุกวัน) เมื่อเวลาผ่านไป 2-3 เดือนถ้าทำตามที่ผมบอกได้คุณจะเห็นทิศทางการขยับที่คุณอยากไปแน่นอน
G35: ความรู้ของผมเป็นเหมือน Walkthrough หรือบทสรุปเกม ที่ช่วยให้เห็นทางว่าแต่ละด่านควรผ่านยังไง มีหลุมกับดักตรงไหนและควรรับมือกับสถานการณ์ต่างๆ ยังไง แต่สุดท้ายแล้ว คุณต้องเป็นคนจับจอยเล่นเอง เพราะผลลัพธ์กว่า 95% อยู่กับการลงมือทำของคุณเอง.
A37: 3.นอน พอเป็นพอ
A38: ผมนอนเฉลี่ยทุกวันแทบจะช่วง ตี 3+ (ปกติมีปัญหานอนเวลาไวแล้วจะตื่นกลางดึกเสมอ) ยังสามารถสร้างกล้ามได้ถ้าคุณมีเวลานอนพอ เพราะฉะนั้น นอนพอ>นอนตรงเวลา ขอให้นอนให้เพียงพอ 6-8ชม.
A39: หากคุณนอนไม่ตรงเวลาแบบผม อาจจะเสียเปรียบด้าน Melatonin อาจจะลดลงไปกระทบการนอน ที่เกี่ยวกับตัวรับแสงอะไรสักอย่างที่เกี่ยวกับ Growth hormone ซึ่งเกี่ยวจริง
A40: แต่ไม่ได้หมายความว่าจะสร้างกล้ามไม่ได้เลยส่วนตัวผมเอง 80% เวลานอนยังกับหมา เลยขอให้นอนพอเป็นพอ | H40: คลิปอธิบายเรื่องนอนดึก
A42: 4.% ไขมัน
A43: ผมแนะนำคงไว้ประมาณ อย่าให้เกิน 15% จะดีต่อฮอรโมนของเรามากที่สุดทางด้านอารมณ์และจิตใจ
A44: ข้อดีของการมี Body fat ประมาณนี้ฮอรโมนจะอยู่ในจุดที่สร้างกล้ามค่อนข้างดีการทำคาร์ดิโอจะไม่หนักตัว รวมถึงดึงข้อเช่นเดียวกัน
A45: ส่วนวัดยังไง ?ผมมีวิธีง่ายที่สุดคือการดูรูปในเน็ทเปรียบเทียบความชัดสักรูปเพราะแต่ละคนเก็บไขมันแต่ละส่วนไม่เท่ากัน
A46: อาจจะ งง อ่าวแล้วมันจะตรงหรอ? กรณีที่คุณไปใช้เครื่องช็อตไฟฟ้าไม่ว่าจะฟิตเนสชื่อดังหรือโรงแรมหรูเครื่องสรรพคุณ 500k+บาท
...

Sheet (ถามตอบก่อนเล่น) ใส่ข้อมูลเฉพาะ
A1: ตอบคำถามก่อนใช้โปรแกรม | G1: จำนวนครั้ง | H1: ประมาณ %1RM | I1: นน. x จำนวนครั้ง | J1: 1RM โดยประมาณ
A2: 1 | B2: เวทเทรนนิ่งมากี่ปี? | D2: 0-2 | G2: 1 ครั้ง | H2: 1 | I2: 100 kg × 1 | J2: 100 kg
A3: 2 | B3: Bench Press 1RM สูงสุด | D3: 130 | E3: KG | G3: 3 ครั้ง | H3: 0.9 | I3: 90 kg × 3
A4: 3 | B4: Overhead Press 1RM สูงสุด | E4: KG | G4: 5 ครั้ง | H4: 0.85 | I4: 85 kg × 5
A5: 4 | B5: Squat 90°,Full 1RM สูงสุด | E5: KG | G5: 8 ครั้ง | H5: 0.8 | I5: 80 kg × 8
A6: 5 | B6: น้ำหนักตัว(ปัจจุบัน) | E6: KG | G6: 10 ครั้ง | H6: 0.75 | I6: 75 kg × 10
A7: 6 | B7: เป้าหมายน้ำหนักตัว | E7: KG | G7: ใครที่ดูแล้วงงไม่ต้องตกใจครับ ใช้สำหรับ คำนวณ PR โดยไม่ต้องเสี่ยงยกน้ำหนักสูงสุดแค่ 1 ครั้ง กรณีใครที่มือใหม่ หรือคำนึงถึงความถึงความปลอดภัย เพื่อนๆสามารถหาได้โดยจำนวนครั้งยก 5-10 ครั้งได้เช่นเดียวกัน
A8: 7 | B8: ดึงข้อได้สูงสุด | E8: ครั้ง
A9: 1RM (One Rep Max) = น้ำหนักมากที่สุดที่สามารถยกได้ 1 ครั้ง
C10: (ด้วยฟอร์มที่ถูกและรวมน้ำหนักบาร์) ไม่นับญาติกับ smith,cable

Sheet คำนวณการกิน
A1: น้ำหนักตัว ปัจจุบัน | B1: ='(ถามตอบก่อนเล่น) ใส่ข้อมูลเฉพาะ'!D6 | C1: กิโล | D1: ตัวอย่างอาหาร ในแต่ละวัน ควรทดแทน ด้วยอาหารอื่นๆ อย่ากินซ้ำทุกวัน (ห้ามข้อมูลกรอกหน้านี้) | E1: อาหาร | G1: จำนวน | H1: หน่วย | I1: ตารางนี้เป็นเพียงตัวอย่างปริมาณอาหารต่อวันเพื่อให้เห็นภาพคร่าว ๆ ไม่จำเป็นต้องกินตามเป๊ะทุกมื้อ และไม่ควรกินเมนูซ้ำทุกวัน ตอนนี่ตัวแคลอาจจะไม่ตรงมากเพราะ ขาดส่วนสูงและอายุ (กำลังแก้)
A2: พลังงานปัจจุบัน/วัน | B2: =IFS( E2="0-2",IF(B3>B1,$B$1*30+200,$B$1*30-300), E2="2-5",IF(B3>B1,$B$1*32+200,$B$1*32-300), E2="5+",$B$1*34+200, TRUE,$B$1*30 ) -> 0 | C2: แคล | E2: อกไก่ | G2: =MAX(0,ROUND((E8*0.8)/45,1)) -> 0 | H2: ชิ้นอกไก่
A3: เป้าหมายน้ำหนัก | B3: ='(ถามตอบก่อนเล่น) ใส่ข้อมูลเฉพาะ'!D7 | C3: กิโล | E3: ไข่ | G3: =ROUND((E8*0.15)/6,0) -> 0 | H3: ฟอง
A4: =IF(OR('(ถามตอบก่อนเล่น) ใส่ข้อมูลเฉพาะ'!D6="",'(ถามตอบก่อนเล่น) ใส่ข้อมูลเฉพาะ'!D7="",'(ถามตอบก่อนเล่น) ใส่ข้อมูลเฉพาะ'!D6=0,'(ถามตอบก่อนเล่น) ใส่ข้อมูลเฉพาะ'!D7=0), "กินเท่าเดิม", IF('(ถามตอบก่อนเล่น) ใส่ข้อมูลเฉพาะ'!D7='(ถามตอบก่อนเล่น) ใส่ข้อมูลเฉพาะ'!D6,"กินเท่าเดิม", IF('(ถามตอบก่อนเล่น) ใส่ข้อมูลเฉพาะ'!D7>'(ถามตอบก่อนเล่น) ใส่ข้อมูลเฉพาะ'!D6,"กินเพิ่มขึ้นวันละ","กินลดลงวันละ"))) -> กินเท่าเดิม | B4: =IF(OR(B1="",B3="",B1=0,B3=0),0, IF(B3=B1,0, IF(ABS(B3-B1)>=10, IF(B3>B1,500,-500), IF(B3>B1,300,-300)))) -> 0 | C4: แคล | E4: ข้าว | G4: =MAX(0,ROUND(E9/22,0)) -> 0 | H4: ทัพพี
A5: พลังงานโดยรวม/วัน | B5: =SUM(B2--B4) -> 0 | C5: แคล | E5: ถั่วลิสงคั่ว | G5: =ROUND(E10/15,0) -> 0 | H5: กำมือ
A7: สารอาหาร | B7: แคล | D7: สัดส่วน | E7: กรัม/วัน | G7: A | H7: =IFS( $G$7="-","⬅️เลือกสูตรด้านซ้ายก่อน", $G$7="A",$H$26, $G$7="B",$H$30, $G$7="C",$H$34 ) -> โปรตีนค่อนข้างสูง ช่วยเพิ่มความอิ่มและรักษามวลกล้ามเนื้อและยังคุมน้ำหนักได้ดี เหมาะสำหรับ • ผู้ที่ต้องการ ลดน้ำหนักหรือควบคุมความหิว • ผู้ที่กำลัง ลดไขมันแต่ยังออกกำลังกาย **Diet ส่วนตัวเน้นเติมเนื้อ ไม่เติมเน็ท**
A8: โปรตีน | B8: =IFERROR(IFS( G7="-","", G7="A",$B$5*0.3, G7="B",$B$5*0.2, G7="C",$B$5*0.2 ),"") -> 0 | D8: =IFS( $G$7="-","", $G$7="A",0.3, $G$7="B",0.2, $G$7="C",0.2 ) -> 0.3 | E8: =ROUND(B8/4,0) -> 0 | F8: g
A9: คาร์บ | B9: =IFS( G7="-","", G7="A",$B$5*0.55, G7="B",$B$5*0.6, G7="C",$B$5*0.65 ) -> 0 | D9: =IFS( $G$7="-","", $G$7="A",0.55, $G$7="B",0.6, $G$7="C",0.65 ) -> 0.55 | E9: =ROUND(B9/4,0) -> 0 | F9: g
A10: ไขมัน | B10: =IFS( G7="-","", G7="A",$B$5*0.15, G7="B",$B$5*0.2, G7="C",$B$5*0.15 ) -> 0 | D10: =IFS( $G$7="-","", $G$7="A",0.15, $G$7="B",0.2, $G$7="C",0.15 ) -> 0.15 | E10: =ROUND(B10/9,0) -> 0 | F10: g
A12: อาหารเสริมที่แนะนำต่อวัน | D12: (ไม่จำเป็นต้องกินหากกินอาหารหลักวในปริมาณที่เหมาะสม)
A14: วิตามิน | B14: ต้องการต่อวัน | D14: หน่วย | E14: คำแนะนำ | H14: ประโยชน์ | J14: Pack
A15: C | B15: =ROUND(B1*10,0)&"–"&ROUND(B1*15,0) -> 0–0 | D15: mg | E15: 1-2 เม็ด Vit C ทั่วไป | H15: ช่วยภูมิคุ้มกัน ลดการอักเสบ และช่วยฟื้นตัว | J15: Starter
A16: D | B16: 2000–4000 | D16: IU | E16: 2 เม็ดหลังอาหาร (กินมั่ว) | H16: ช่วยระบบพลังงานของร่างกายและระบบประสาท
A17: B รวม | B17: ="1" -> 1 | D17: เม็ด | E17: 1 เม็ด | H17: ช่วยฮอร์โมน กระดูก และกล้ามเนื้อ
A18: Creatine | B18: 3–5 | D18: g | E18: วันละสกูป | H18: เพิ่มแรง เพิ่มพลัง และช่วยรักษากล้ามเนื้อ
A19: Magnesium | B19: =ROUND(B2*4,0)&"–"&ROUND(B2*5.5,0) -> 0–0 | D19: mg | E19: ก่อนนอน 1 เม็ด | H19: ช่วยการฟื้นตัวของกล้ามเนื้อ การนอน และระบบประสาท | J19: Premuim
A20: Creatine | B20: 3–5 | D20: g | E20: วันละสกูป | H20: เพิ่มแรง เพิ่มพลัง และช่วยรักษากล้ามเนื้อ
A21: Omega-3 | B21: =ROUND(B1*14,0)&"–"&ROUND(B1*28,0) -> 0–0 | D21: mg | E21: 1-2 เม็ดหลังอาหาร | H21: ช่วยลดการอักเสบ หัวใจ และข้อต่อ
A22: Zinc | B22: =ROUND(B1*0.14,0)&"–"&ROUND(B1*0.2,0) -> 0–0 | D22: mg | E22: 1 เม็ด zinc ทั่วไป | H22: ช่วยฮอร์โมนเพศชาย
A24: Build สัดส่วนอาหาร A,B,C
A26: สารอาหาร | B26: แคล | D26: สัดส่วน | E26: กรัม/วัน | G26: A | H26: โปรตีนค่อนข้างสูง ช่วยเพิ่มความอิ่มและรักษามวลกล้ามเนื้อและยังคุมน้ำหนักได้ดี เหมาะสำหรับ • ผู้ที่ต้องการ ลดน้ำหนักหรือควบคุมความหิว • ผู้ที่กำลัง ลดไขมันแต่ยังออกกำลังกาย **Diet ส่วนตัวเน้นเติมเนื้อ ไม่เติมเน็ท**
A27: โปรตีน | B27: 750 | D27: 0.3 | E27: 188 | F27: g
A28: คาร์บ | B28: 1375 | D28: 0.55 | E28: 344 | F28: g
A29: ไขมัน | B29: 375 | D29: 0.15 | E29: 42 | F29: g
A30: สารอาหาร | B30: แคล | D30: สัดส่วน | E30: กรัม/วัน | G30: B | H30: สัดส่วน โปรตีน,คาร์บ,ไขมัน ค่อนข้างสมดุล เหมาะสำหรับ • มือใหม่ที่เริ่มออกกำลังกาย (เลือกกินง่าย) • ผู้ที่ต้องการ สร้างกล้ามเนื้อและลดไขมันไปพร้อมกัน (Recomposition) • ผู้ที่ยังไม่แน่ใจว่าจะเลือกสัดส่วนแบบไหน **สร้างกล้ามหลักลดไขมันลอง,มือใหม่เริ่มแรกคิดไม่ออกเลือกอันนี้**
A31: โปรตีน | B31: 500 | D31: 0.2 | E31: 125 | F31: g
A32: คาร์บ | B32: 1500 | D32: 0.6 | E32: 375 | F32: g
A33: ไขมัน | B33: 500 | D33: 0.2 | E33: 56 | F33: g
A34: สารอาหาร | B34: แคล | D34: สัดส่วน | E34: กรัม/วัน | G34: C | H34: คาร์บค่อนข้างสูง ช่วยเพิ่มพลังงานและช่วยให้ฝึกได้หนักขึ้น เหมาะสำหรับ • ผู้ที่ ฝึกหนักหรือใช้พลังงานสูง • คาร์บ่อยหรือมีกิจกรรมรอง,หลัก,อย่างเล่น บอล,วิ่ง,ว่ายน้ำ,มวย 108+ **คาร์บเยอะกรณีทำกิจกรรมเยอะ**
A35: โปรตีน | B35: 500 | D35: 0.2 | E35: 125 | F35: g
A36: คาร์บ | B36: 1750 | D36: 0.7 | E36: 438 | F36: g
A37: ไขมัน | B37: 250 | D37: 0.1 | E37: 28 | F37: g
A39: สัดส่วนโภชนาการไม่มีหลักสูตรตายตัวขึ้นอยู่กับเป้าหมายเราและกรรมพันธุ์อยากให้ลองให้หลายรูปแบบแม้แต่นอกโปรแกรมผมเอง
A40: ข้อมูลนี้เป็นแนวทาง ไม่จำเป็นต้องกินเป๊ะ 100% ช่วงแรกคำนวณเพื่อให้กะปริมาณพอเป็น พอจับทริคได้ก็จะประมาณเองได้ว่ากินพอหรือยังทุกวันนี้ผมก็ไม่ได้ชั่งหรือนับแล้วนอกสะจาก นน.ตัวเยอะ
J41: License - Baygeta
J42: สามารถคัดลอก แก้ไข และแจกจ่ายไฟล์นี้ได้อิสระ ห้ามนำไปขายหรือใช้เพื่อการค้า

Sheet อก A
A1: No. | B1: Exercise | C1: Weight(Kg) | D1: Sets | E1: Reps | F1: Rest | G1: Tips | H1: Group Muscle
A2: ลำดับ | B2: ชื่อท่า | C2: นน. | D2: เซต | E2: ครั้ง | F2: พัก | G2: แนะนำ | H2: กลุ่มกล้ามเนื้อ
A3: 1 | B3: เลือกท่าใดก็ได้ (รอบหน้าสลับ) 🔄 | C3: =IFS( B3="เลือกท่าใดก็ได้ (รอบหน้าสลับ) 🔄","", B3="","", B3="Bench Press (Strength)",ROUND('(ถามตอบก่อนเล่น) ใส่ข้อมูลเฉพาะ'!D3*0.8,0), B3="Bench Press (Hyper)",ROUND('(ถามตอบก่อนเล่น) ใส่ข้อมูลเฉพาะ'!D3*0.7,0) ) | D3: =IFS( B3="เลือกท่าใดก็ได้ (รอบหน้าสลับ) 🔄","", C3="-","", B3="Bench Press (Strength)","3-5", B3="Bench Press (Hyper)","4-5" ) | E3: =IFS( B3="เลือกท่าใดก็ได้ (รอบหน้าสลับ) 🔄","", C3="-","", B3="Bench Press (Strength)","3-5", B3="Bench Press (Hyper)","8-12" ) | F3: =IF(B3="เลือกท่าใดก็ได้ (รอบหน้าสลับ) 🔄","",2) | G3: =IF(B3="เลือกท่าใดก็ได้ (รอบหน้าสลับ) 🔄","**เลือกท่าก่อนเล่นให้สลับกันแต่ละครั้งส่วนถ้าใครไม่ได้เล่นต่อเนื่องหรือฟรอมยังไม่เป๊ะให้เลือก Hyper**", IF(B3="Bench Press (Strength)", "-แนะนำให้วรอมเปิดด้วยท่า Tricep หลังแขนเล่นประมาณ 20%-40% ของน้ำหนักจริง เผื่อเป็นการวรอมหลังแขน -จากนั้นไต่น้ำหนักจากการเล่น Bench Press 40%=>60%=>80=>น้ำหนักจริง -การเล่น Strength จะทำให้พัฒนาได้ดีแต่มีทั้งข้อดีและเสีย High Risk Hight Reward ใครที่เป็นม"&"ือใหม่พึ่งเข้ายิมแนะนำให้ สลับไปเล่น Hyperthophy จนฟรอมส์เป๊ะแล้วจริงๆค่อยมาเล่นแบบ Strength ส่วนประสบการณ์ขั้นต่ำหากมือใหม่เลย 6 เดือน+ ถึงค่อยเล่นรูปแบบนี้", IF(B3="Bench Press (Hyper)", "--ก่อนจะเล่นแนะนำไต่น้ำหนัก 🪜 40%,60%,80% => น้ำหนักจริง -จำนวน Rep จะค่อยๆ ลดลงไม่ต้องตกใจ แต่อย่าต่ำกว่า 6 เป็นพอ -สะบักกับก้น 4 จุดแตะกับเบาะเหมือนขาเก้าอี้ 🪑 -บาร์แตะกับลิ้นปี่ใต้หัวนมเล็กน้อย ตอนออกแรงให้เพื่อนดูจากข้างๆต้องขึ้นเป็นเส้นตรง -ท่าเดีย"&"วของวันนี้ที่ควรหาคนเซฟ"))) -> **เลือกท่าก่อนเล่นให้สลับกันแต่ละครั้งส่วนถ้าใครไม่ได้เล่นต่อเนื่องหรือฟรอมยังไม่เป๊ะให้เลือก Hyper** | H3: อก
A4: 2 | B4: เลือกท่าใดก็ได้ (รอบหน้าสลับ) 🔄 | C4: =IF(B4="เลือกท่าก่อนเล่น","", IF(B4="Incline Dumbbell Press (ข้างละ)", ROUND(('(ถามตอบก่อนเล่น) ใส่ข้อมูลเฉพาะ'!D3*0.65)/2* IF('(ถามตอบก่อนเล่น) ใส่ข้อมูลเฉพาะ'!$D$2="Hard",0.9, IF('(ถามตอบก่อนเล่น) ใส่ข้อมูลเฉพาะ'!$D$2="Normal",0.8, IF('(ถามตอบก่อนเล่น) ใส่ข้อมูลเฉพาะ'!$D$2="Easy",0.7,0.9))),0), IF(B4="Incline Smith Chest Press", ROUND(('(ถามตอบก่อนเล่น) ใส่ข้อมูลเฉพาะ'!D3*0.77)* IF('(ถามตอบก่อนเล่น) ใส่ข้อมูลเฉพาะ'!$D$2="Hard",0.85, IF('(ถามตอบก่อนเล่น) ใส่ข้อมูลเฉพาะ'!$D$2="Normal",0.75, IF('(ถามตอบก่อนเล่น) ใส่ข้อมูลเฉพาะ'!$D$2="Easy",0.68,0.85))),0),""))) | D4: =IF(C4="-","", IF('(ถามตอบก่อนเล่น) ใส่ข้อมูลเฉพาะ'!$D$2="5+","4", IF('(ถามตอบก่อนเล่น) ใส่ข้อมูลเฉพาะ'!$D$2="2-4","3-4", IF('(ถามตอบก่อนเล่น) ใส่ข้อมูลเฉพาะ'!$D$2="0-2","3","3")))) | E4: =IFS( B4="เลือกท่าก่อนเล่น","", C4="-","", B4="Incline Dumbbell Press (ข้างละ)","8-10", B4="Incline Smith Chest Press","8-10" ) | F4: =IF(B4="เลือกท่าใดก็ได้ (รอบหน้าสลับ) 🔄","",2) | G4: =IF(B4="เลือกท่าใดก็ได้ (รอบหน้าสลับ) 🔄","**เลือกท่าก่อนเล่นให้สลับกันแต่ละครั้ง ตัวอย่าง : รอบนี้เล่น Smith รอบหน้าเล่น Dumbbells แทน**", IF(B4="Incline Dumbbell Press (ข้างละ)", "-เซ็ทแรกแนะนำเล่นน้ำหนัก 80% แต่เพิ่มจำนวนครั้งสัก 2-3 ครั้งเพื่อกันบาดเจ็บข้อมือ -ถ้าเหนื่อยจากการ Take ให้วางดัมเบลที่เข่าสัก 5-20 วิ ค่อยเล่น -ใช้เข่า Take ทุกครั้งก่อนจะเล่น -เบาะ 45°", IF(B4="Incline Smith Chest Press", "-เซ็ทบาร์ให้ลงเหนือหัวนมเล็กน้อย ให้บาร์ตกช่วงอกบนหน่อยๆ -ก้นล็อคกับเบาะไม่ก้นลอยหรือขยับไปมา สะบักกับก้น 4 จุดแตะกับเบาะเหมือนขาเก้าอี้ 🪑 -ลงสุด ดันขึ้นสุดแต่ล็อคศอกประมาณ 95% -เบาะ 45°",""))) -> **เลือกท่าก่อนเล่นให้สลับกันแต่ละครั้ง ตัวอย่าง : รอบนี้เล่น Smith รอบหน้าเล่น Dumbbells แทน**
A5: 3 | B5: เลือกท่าตามมัดที่ด้อย 🎯 ก่อนเล่น | C5: =SWITCH(B5, "Bench Press",104, "Incline Dumbbell Press (ข้างละ)",38, "Machine Fly (อกกลาง)","ความหนัก 8/10", "Cable Dips","ความหนัก 8/10", "Triceps Pushdown Straight Bar","ความหนัก 9-10/10", "Triceps Rope Pushdown","ความหนัก 6/10", "Overhead Rope Triceps Extension","ความหนัก 5/10", "Tricep Cable Kickback","ความหนัก 7/10", "Cable Fly Incline (อกบน)","ความหนัก 7/10", "Cable Fly (อกกลาง)","ความหนัก 7/10", "Cable Fly Decline (อกล่าง)","ความหนัก 7/10", "Dumbbells Incline Fly (อกบน)","ความหนัก 6-7/10", "Dumbbells Fly (อกกลาง)","ความหนัก 6-7/10", "") | D5: =SWITCH(B5, "Bench Press",4, "Incline Dumbbell Press (ข้างละ)",4, "Machine Fly (อกกลาง)",4, "Cable Dips",4, "Triceps Pushdown Straight Bar",4, "Triceps Rope Pushdown",3, "Overhead Rope Triceps Extension",3, "Tricep Cable Kickback",4, "Cable Fly Incline (อกบน)",4, "Cable Fly (อกกลาง)",4, "Cable Fly Decline (อกล่าง)",4, "Dumbbells Incline Fly (อกบน)",4, "Dumbbells Fly (อกกลาง)",4, "") | E5: =SWITCH(B5, "Bench Press","5-8", "Incline Dumbbell Press (ข้างละ)","8-12", "Machine Fly (อกกลาง)","8-12", "Cable Dips","8-12", "Triceps Pushdown Straight Bar","7-10", "Triceps Rope Pushdown","10-12", "Overhead Rope Triceps Extension","8-12", "Tricep Cable Kickback","12-15", "Cable Fly Incline (อกบน)","10-12", "Cable Fly (อกกลาง)","10-12", "Cable Fly Decline (อกล่าง)","10-12", "Dumbbells Incline Fly (อกบน)","10-15", "Dumbbells Fly (อกกลาง)","10-15", "") | F5: =SWITCH(B5, "Bench Press","2-3", "Incline Dumbbell Press (ข้างละ)","2", "Machine Fly (อกกลาง)","1:30", "Cable Dips","2", "Triceps Pushdown Straight Bar","2", "Triceps Rope Pushdown","1:30", "Overhead Rope Triceps Extension","1:30", "Tricep Cable Kickback","1:30", "Cable Fly Incline (อกบน)","1", "Cable Fly (อกกลาง)","1", "Cable Fly Decline (อกล่าง)","1", "Dumbbells Incline Fly (อกบน)","1", "Dumbbells Fly (อกกลาง)","1", "") | G5: =SWITCH(B5, "เลือกท่าตามมัดที่ด้อย 🎯 ก่อนเล่น", "**เลือกท่าก่อนเล่น และสลับท่าในแต่ละรอบ เช่นรอบนี้เล่น Machine รอบหน้า Cable**", "Incline Dumbbell Press (ข้างละ)", "-เซ็ทแรกแนะนำใช้น้ำหนักประมาณ 80% แต่เพิ่มจำนวนครั้ง 2-3 ครั้งเพื่อกันบาดเจ็บข้อมือ -ถ้าเหนื่อยจากการ Take ให้วางดัมเบลที่เข่าสัก 5-20 วินาทีแล้วค่อยเริ่มเล่น -ใช้เข่า Take ทุกครั้งก่อนเริ่มเล่น "&#REF!&" -ปรับเบาะประมาณ 45°", "Incline Smith Chest Press", "-ตั้งบาร์ให้ลงเหนือหัวนมเล็กน้อย เพื่อให้โดนอกบน -ก้นและสะบักล็อคกับเบาะ ไม่ขยับ สัมผัสเบาะ 4 จุดเหมือนขาเก้าอี้ -ลงสุด ดันขึ้นสุด แต่ล็อคศอกประมาณ 95% -ปรับเบาะประมาณ 45°", "Cable Fly Incline (อกบน)", "-เหมาะสำหรับอกบนด้อยโดนไหล่แซง -เล่นแบบไขว้แขน (Cross) สลับทุกเซ็ท เช่น เซ็ทแรกซ้ายทับขวา เซ็ทต่อไปขวาทับซ้าย -ยืนให้มั่นคง จะยืนปกติหรือยืนไขว้ขาก็ได้", "Cable Fly (อกกลาง)", "-เป็นมุมมาตรฐานสำหรับฟาร์มกล้ามอกโดยรวม -เล่นแบบไขว้แขน (Cross) สลับทุกเซ็ท เช่น เซ็ทแรกซ้ายทับขวา เซ็ทต่อไปขวาทับซ้าย -ยืนให้มั่นคง จะยืนปกติหรือยืนไขว้ขาก็ได้", "Cable Fly Decline (อกล่าง)", "-ใช้เน้นอกล่าง -เล่นแบบไขว้แขน (Cross) สลับทุกเซ็ท เช่น เซ็ทแรกซ้ายทับขวา เซ็ทต่อไปขวาทับซ้าย -ตอนเล่นจำลองให้เหมือนเรากำลัง Dips ตัวให้ลอยโดยใช้อก -ยืนให้มั่นคง,หรือจะคุกเข่าก็ได้", "Dumbbells Incline Fly (อกบน)", "-เหมาะกับคนที่อกบนด้อย -ใช้เข่า Take ก่อนเริ่มเล่น -ปรับเบาะประมาณ 45° -ตอนลงยืดอกให้สุด ตอนขึ้นบีบอก", "Dumbbells Fly (อกกลาง)", "-เน้นอกกลาง -ใช้เข่า Take ทุกครั้งก่อนเริ่มเล่น -บีบอกให้สุดก่อนแขนมาชนกัน", "Machine Fly (อกกลาง)", "-ปรับระยะด้ามจับให้เลยศอกเล็กน้อย -ศอกงอประมาณ 75-80% ตอนออกแรงสุดระยะสามารถดันไปได้ 95% -นึกถึงกล้ามอกหนีบเข้าหากันแบบกล้ามปูหนีบ🦀 -(ส่วนตัวชอบท่านี้ที่สุดแต่ต้องเล่นสลับกับ Cable)", "") -> **เลือกท่าก่อนเล่น และสลับท่าในแต่ละรอบ เช่นรอบนี้เล่น Machine รอบหน้า Cable**
A6: 4 | B6: Cable Dips | C6: ความหนัก 8/10 | D6: =SWITCH('(ถามตอบก่อนเล่น) ใส่ข้อมูลเฉพาะ'!$D$2, "5+","4", "2-4","3-4", "0-2","3") -> 3 | E6: 10–12 | F6: 0.0625 | G6: -เอนตัวข้างหน้าเล็กน้อยเพื่อให้โดนอก -ส่วนตัวชอบคุกเข่าเล่น โฟกัสอกง่ายกว่าไม่ต้องพะวงตัว -ตอนออกแรงให้จำรองว่ากำลังใช้อก Dips ตัวเองให้ลอยกับบาร์สุดแขนตอนสุดระยะอกทำงาน -ไม่เหวี่ยงตัว ถ้าเกิน 8+ Reps แล้วไม่ไหว สามารถ Cheats 💥 โยกตัวเล็กน้อยเพื่อจบเซ็ต
A7: 5 | B7: Triceps Pushdown Straight Bar | C7: =IF('(ถามตอบก่อนเล่น) ใส่ข้อมูลเฉพาะ'!$D$2="5+","ความหนัก 9-10/10", IF('(ถามตอบก่อนเล่น) ใส่ข้อมูลเฉพาะ'!$D$2="2-4","ความหนัก 8/10", IF('(ถามตอบก่อนเล่น) ใส่ข้อมูลเฉพาะ'!$D$2="0-2","ความหนัก 7-8/10", "ความหนัก 9-10/10"))) -> ความหนัก 7-8/10 | D7: =IF('(ถามตอบก่อนเล่น) ใส่ข้อมูลเฉพาะ'!$D$2="5+","3-4", IF('(ถามตอบก่อนเล่น) ใส่ข้อมูลเฉพาะ'!$D$2="2-4","3-4", IF('(ถามตอบก่อนเล่น) ใส่ข้อมูลเฉพาะ'!$D$2="0-2","3","3"))) -> 3 | E7: 7–10 | F7: 2 | G7: -ก่อนจะเล่นแนะนำไต่น้ำหนัก 🪜40%,60%,80% ของน้ำหนักที่เล่นจริง -ศอกขนานกับตัว ใช้บาร์ V หรือ บาร์ตรง -ศอกขยับขึ้นได้เล็กน้อยแต่ตอนเล่นกดลงให้สุดแขนจาก 100% ระยะออกแรง -ไม่ใช้บ่า+เหวี่ยงตัว ถ้าเกิน 6+ Reps แล้วไม่ไหว สามารถ Cheats 💥 โยกตัวเล็กน้อยเพื่อจบเซ็ต | H7: หลังแขน
A8: 6 Super Sets | B8: Triceps Rope Pushdown | C8: ความหนัก 6/10 | D8: 3 | E8: 10 | F8: 0.0625 | G8: -เล่นเหมือนจ่าพนมช้างกูอยู่ไหน 🐘 ศอกเลยนำหน้าตัวเล็กน้อย ใช้มือบิดเชือกฉีกออกข้างให้สุด เพื่อให้หลังแขนหดตัวและบีบกล้ามช่วงล่างเต็ม -จับเชือกให้ฝ่ามือชนตุ่มดำของ Rope เพื่อลดแรงกำ จะได้ออกแรงแขนได้เต็มที่ (ส่วนตัวไม่ใช้นิ้วโป้งกำ) -ศอกพยายามล็อคให้นิ่ง ถ้าเกิน 8+ Reps แล้วไม่ไหว สามารถ Cheats 💥 เล็กน้อยเพื่อจบเซ็ต
B9: Overhead Rope Triceps Extension | C9: ความหนัก 5/10 | E9: จนหมด 7+ | G9: -ท่ามี Cable สองฝั่งก็ดีแต่ถ้าคนเยอะปรับแปปๆไม่เป็นไร ลดน้ำหนักท่าที่แล้วลง 10-20% -ส่วนตัวเอาก้น 1 ข้างชิดกับเครื่อง Cable ไปเลย -ระยะตอนออกแรงต้องลงสุดไม่มีเสียงเหล็กกระทบ -เล่นจนหมดไม่ต้องเหลือแรง Cheats 💥ไม่ค่อยแนะนำมุมมันตึงสุดๆแล้ว หมดเท่าไหนเท่านั้น
A10: 7 | B10: Tricep Cable Kickback | C10: ความหนัก 7/10 | D10: =IF('(ถามตอบก่อนเล่น) ใส่ข้อมูลเฉพาะ'!$D$2="5+","3-4", IF('(ถามตอบก่อนเล่น) ใส่ข้อมูลเฉพาะ'!$D$2="2-4","3", IF('(ถามตอบก่อนเล่น) ใส่ข้อมูลเฉพาะ'!$D$2="0-2","3","3"))) -> 3 | E10: 12–15 | F10: 1 | G10: -เซ็ต Cable ระดับต่ำสุดหรือหน้าแข้ง ถอดด้ามจับออก เหลือลูกยางกันกระแทก แล้วก็กำไอลูกนั้นแหละ -ช่วงต้นแขนอยู่นิ่ง ให้ระยะองศาแขนขนานกับพื้นหรือมากกว่า 180+° s หรือจะก้มต่ำสุดๆให้ระยะออกแรงแรกยากสุด -เล่นทีละข้างจะทำให้กล้ามเรา Balance มากขึ้น และปรับความต่างของแขนซ้ายขวา -ตอนวางระวังลูกยางกินนิ้ว -กรณีไม่ถึง Cheats 💥โดยใช้อีกมือเซฟ แต่อย่าช่วยเยอะจ่ายแรงพอควร (ควรเซฟครั้งที่ 10Reps+)
A11: โปรแกรมเป็นเพียงแนวทาง ปรับ Volume ตามสภาพร่างกายและการฟื้นตัวของตัวเองเป็นหลัก อย่าฝืนซ้อมหากร่างกายส่งสัญญาณว่าพักไม่พอ | H11: License - Baygeta
A12: พักตามความพร้อมของร่างกาย (แนะนำเล่นต่อเนื่อง 4–6 วัน) แล้วนับต่อจากวันที่เล่นล่าสุด | H12: สามารถคัดลอก แก้ไข และแจกจ่ายไฟล์นี้ได้อิสระ ห้ามนำไปขายหรือใช้เพื่อการค้า

Sheet หลัง A
A1: No. | B1: Exercise | C1: Weight(Kg) | D1: Sets | E1: Reps | F1: Rest | G1: Tips | H1: Group Muscle
A2: ลำดับ | B2: ชื่อท่า | C2: นน. | D2: เซต | E2: ครั้ง | F2: พัก | G2: แนะนำ | H2: กลุ่มกล้ามเนื้อ
A3: 1 | B3: Lat Pulldown | C3: =IF('(ถามตอบก่อนเล่น) ใส่ข้อมูลเฉพาะ'!$D$2="5+","ความหนัก 9-10/10", IF('(ถามตอบก่อนเล่น) ใส่ข้อมูลเฉพาะ'!$D$2="2-4","ความหนัก 8/10", IF('(ถามตอบก่อนเล่น) ใส่ข้อมูลเฉพาะ'!$D$2="0-2","ความหนัก 8/10", "ความหนัก 9-10/10"))) -> ความหนัก 8/10 | D3: =IF('(ถามตอบก่อนเล่น) ใส่ข้อมูลเฉพาะ'!$D$2="5+",5, IF('(ถามตอบก่อนเล่น) ใส่ข้อมูลเฉพาะ'!$D$2="2-4","4", IF('(ถามตอบก่อนเล่น) ใส่ข้อมูลเฉพาะ'!$D$2="0-2","3-4","3-4"))) -> 3-4 | E3: 7–10 | F3: 46083 | G3: -ก่อนจะเล่นแนะนำไต่น้ำหนัก🪜 50%,70%,80% => น้ำหนักจริง -ขึ้นสุด ตอนลงหากด้อยปีกแนะนำให้ลงต่ำกว่าคางเล็กน้อยแต่ไม่ต้องแตะอก -ให้หลังทำงานก่อนแขนเสมอ เมื่อแรงหมดให้ใช้ตัวโยกโกงเอา Cheats 💥 ครั้งที่ 7+ ขึ้นไป | H3: หลัง
A4: 2 | B4: Cable Seated Row | C4: ความหนัก 7/10 | D4: =IF('(ถามตอบก่อนเล่น) ใส่ข้อมูลเฉพาะ'!$D$2="5+",5, IF('(ถามตอบก่อนเล่น) ใส่ข้อมูลเฉพาะ'!$D$2="2-4","4", IF('(ถามตอบก่อนเล่น) ใส่ข้อมูลเฉพาะ'!$D$2="0-2","3-4","3-4"))) -> 3-4 | E4: 8–14 | F4: 0.0625 | G4: -หลังตรง 90องศา° -เปิดหน้าอกรับ ออกแรงผ่านศอกดึงให้เลยหลัง -ให้หลังทำงานก่อนแขนเสมอ เมื่อแรงหมดให้ใช้ตัวโยกโกงเอา Cheats 💥 ครั้งที่ 10+ ขึ้นไป
A5: 3 | B5: Close-Grip Pulldown | C5: =IF('(ถามตอบก่อนเล่น) ใส่ข้อมูลเฉพาะ'!$D$2="5+","ความหนัก 9-10/10", IF('(ถามตอบก่อนเล่น) ใส่ข้อมูลเฉพาะ'!$D$2="2-4","ความหนัก 8/10", IF('(ถามตอบก่อนเล่น) ใส่ข้อมูลเฉพาะ'!$D$2="0-2","ความหนัก 8/10", "ความหนัก 9-10/10"))) -> ความหนัก 8/10 | D5: =IF('(ถามตอบก่อนเล่น) ใส่ข้อมูลเฉพาะ'!$D$2="5+","5", IF('(ถามตอบก่อนเล่น) ใส่ข้อมูลเฉพาะ'!$D$2="2-4","3-4", IF('(ถามตอบก่อนเล่น) ใส่ข้อมูลเฉพาะ'!$D$2="0-2","3","3-4"))) -> 3 | E5: 7–10 | F5: 46083 | G5: -ขึ้นสุดลงต่ำกว่าคางแต่ไม่ต้องแตะหน้าอก -ใช้หลังแขนทำงานก่อนไม่ไหวค่อยใช้หน้าแขนช่วยเอาทีหลัง -ท่านี้อย่ากลัวว่าจะโดนหน้าแขน มันโดนอยู่แล้ว 30% ให้หลังทำงานก่อนแขนเสมอ เมื่อแรงหมดให้ใช้ตัวโยกโกงเอา Cheats 💥 ครั้งที่ 7+ ขึ้นไป
A6: 4 | B6: เลือกท่าใดก็ได้ (รอบหน้าสลับ) 🔄 | C6: =IF(B6="เลือกท่าก่อนเล่น","", IF(B6="T-Bar Row","ความหนัก 8/10", IF(B6="T-Bar Dumbbells Row","ความหนัก 7/10",""))) | D6: =IF(B6="เลือกท่าก่อนเล่น","", IF(B6="T-Bar Row","4", IF(B6="T-Bar Dumbbells Row","4",""))) | E6: =IF(B6="เลือกท่าก่อนเล่น","", IF(B6="T-Bar Row","10-12", IF(B6="T-Bar Dumbbells Row","12-15",""))) | F6: =IF(B6="เลือกท่าก่อนเล่น","", IF(B6="T-Bar Row","1:30", IF(B6="T-Bar Dumbbells Row","1",""))) | G6: =IF(B6="เลือกท่าหลัง", "**โปรดเลือกท่าก่อนเล่นให้สลับกันแต่ละครั้ง ตัวอย่าง : รอบนี้เล่น T-Bar รอบหน้าเล่น Dumbbells แทน**", IF(B6="T-Bar Row", "-Grip ให้จับแบบกว้างเล็กน้อยเพื่อเน้นหลังบน -ตอนดึงให้คิดว่าดึกศอกขึ้น ไม่ใช่ดึงด้วยมือคิดสะว่าดึงให้ศอกเลยหลัง -หน้าอกแตะเบาะตลอด อย่าเหวี่ยงตัว -ดึงขึ้นสุดแล้วบีบสะบักเข้าหากัน", IF(B6="T-Bar Dumbbells Row", "-ปรับเบาะประมาณ 45° -หลังตรง อย่าค่อม -ปล่อยแขนลงสุดทุกครั้ง -ท่อน Forearm เหมือนเชือกห้อยไว้ ตอนดึงให้นึกถึงศอกเลยหลัง -เมื่อแรงหมดให้ใช้ตัวโยกโกงตัวเบาๆเอา Cheats 💥 ครั้งที่ 10+ ขึ้นไป(ระวังหลังเดาะ) ","")))
A7: Super Sets | B7: Straight-Arm Pulldown | C7: ความหนัก 7/10 | D7: 4 | E7: 12-15 | G7: -ท่านี้ปราบเซียนสอนยากแนะนำให้ถ่ายคลิปตัวเองตอนเล่นเปรียบเทียบกับคนที่ฟรอมส์ดีๆ -แนะนำให้ลองเล่นผิดท่าโดยใช้หลังแขนตัวเองก่อน จากนั้นค่อยตัดการใช้กล้ามเนื้อมัดหลังแขนออก -หมุนเฟืองเหมือนปีนหน้าผาโดยที่ท่อน Fore arm ขาดไปลากลงมาสุดจนบาร์กระทบขาหรือเกือบกระทบขา -ท่องไว้ว่า Straight แขนต้องตรึงสุด 100%ตอนขึ้น ตอนออกแรงลงมาศอกงอประมาณ 80-90%
A8: 5 | B8: Dumbell Hammer Curl | C8: =IF('(ถามตอบก่อนเล่น) ใส่ข้อมูลเฉพาะ'!$D$2="5+","ความหนัก 9-10/10", IF('(ถามตอบก่อนเล่น) ใส่ข้อมูลเฉพาะ'!$D$2="2-4","ความหนัก 8/10", IF('(ถามตอบก่อนเล่น) ใส่ข้อมูลเฉพาะ'!$D$2="0-2","ความหนัก 7-8/10", "ความหนัก 9-10/10"))) -> ความหนัก 7-8/10 | D8: =IF('(ถามตอบก่อนเล่น) ใส่ข้อมูลเฉพาะ'!$D$2="5+","4-5", IF('(ถามตอบก่อนเล่น) ใส่ข้อมูลเฉพาะ'!$D$2="2-4","3-4", IF('(ถามตอบก่อนเล่น) ใส่ข้อมูลเฉพาะ'!$D$2="0-2","3","3-4"))) -> 3 | E8: 7–10 | F8: 46083 | G8: -🪜ก่อนจะเล่นแนะนำไต่น้ำหนัก🪜 30%,50%,80% => น้ำหนักจริง -ท่านี้สำคัญเล่นให้หนัก แต่ก็วัดความเสี่ยงเจ็บเราด้วย อย่างผมเองก็ถ้ารู้สึกแป๊ดๆหน่อยๆก็หยุดแล้วเสริมด้วยท่าอื่นๆแทนอย่าง Cocentrat Curl ลดน้ำหนักลง 30-40% -ศอกติดข้างลำตัว ถ้าออกแรงระยะเกิน 70%+พุ่งศอกมาข้างหน้าได้เล็กน้อยจากนั้นกลับไปที่เดิม -เมื่อแรงหมดให้ใช้ตัวโยกโกงเอา Cheats 💥 ครั้งที่ 6+ ขึ้นไป ระวังเจ็บพอ | H8: หน้าแขน
A9: 6 | B9: Dumbell Bicep Curl | C9: ความหนัก7-8/10 | D9: =IF('(ถามตอบก่อนเล่น) ใส่ข้อมูลเฉพาะ'!$D$2="5+","4", IF('(ถามตอบก่อนเล่น) ใส่ข้อมูลเฉพาะ'!$D$2="2-4","3-4", IF('(ถามตอบก่อนเล่น) ใส่ข้อมูลเฉพาะ'!$D$2="0-2","3","3"))) -> 3 | E9: 46366 | F9: 0.0625 | G9: -เล่นแบบปกติเลย Curl ไม่ต้องดามท้อง ไม่ต้องดึงศอกไปข้างหลัง -ศอกติดข้างลำตัวเสมออาจขยับไปข้างหน้าได้แบบเดียวกันกับท่า Hammer แต่น้อยกว่า -เมื่อแรงหมดให้ใช้ตัวโยกโกงเอา Cheats 💥 ครั้งที่ 8+ ขึ้นไป ระวังเจ็บพอ
A10: โปรแกรมเป็นเพียงแนวทาง ปรับ Volume ตามสภาพร่างกายและการฟื้นตัวของตัวเองเป็นหลัก อย่าฝืนซ้อมหากร่างกายส่งสัญญาณว่าพักไม่พอ | H10: License - Baygeta
A11: พักตามความพร้อมของร่างกาย (แนะนำเล่นต่อเนื่อง 4–6 วัน) แล้วนับต่อจากวันที่เล่นล่าสุด | H11: สามารถคัดลอก แก้ไข และแจกจ่ายไฟล์นี้ได้อิสระ ห้ามนำไปขายหรือใช้เพื่อการค้า

Sheet ไหล่ A
A1: No. | B1: Exercise | C1: Weight(Kg) | D1: Sets | E1: Reps | F1: Rest | G1: Tips | H1: Group Muscle
A2: ลำดับ | B2: ชื่อท่า | C2: นน. | D2: เซต | E2: ครั้ง | F2: พัก | G2: แนะนำ | H2: กลุ่มกล้ามเนื้อ
A3: 1 | B3: BarBell Overhead Press | C3: =MROUND( ('(ถามตอบก่อนเล่น) ใส่ข้อมูลเฉพาะ'!D4*0.725) * IF('(ถามตอบก่อนเล่น) ใส่ข้อมูลเฉพาะ'!$D$2="Hard",1, IF('(ถามตอบก่อนเล่น) ใส่ข้อมูลเฉพาะ'!$D$2="Normal",0.9, IF('(ถามตอบก่อนเล่น) ใส่ข้อมูลเฉพาะ'!$D$2="Easy",0.8,1))) ,2.5) -> 0 | D3: =IF('(ถามตอบก่อนเล่น) ใส่ข้อมูลเฉพาะ'!$D$2="5+",5, IF('(ถามตอบก่อนเล่น) ใส่ข้อมูลเฉพาะ'!$D$2="2-4","4", IF('(ถามตอบก่อนเล่น) ใส่ข้อมูลเฉพาะ'!$D$2="0-2","3","3"))) -> 3 | E3: 5 | F3: 4 + (ตามฟิล) | G3: -ก่อนจะเล่นแนะนำไต่น้ำหนัก 40% 60% 80% => น้ำหนักจริง -อย่าแอ่นหลังแบบ 100% ไม่งั้นจะเป็นการใช้กระดูกดาม เหลือสัก 90-95% -กลั้นหายใจเกร็งหน้าท้องเหมือนจะโดนต่อยทุกครั้งที่ออกแรงพอผ่านระยะ 70%+ หายใจออกได้ -บีบก้นเกร็งหน้าท้องกันหลังแอ่น ศีรษะถอยตอนบาร์ผ่านหน้าแล้วดันหัวกลับไปตอนออกแรง -ถ้ามีเข็มขัดใส่บล็อคหลังทุกครั้งที่พยายามขึ้นน้ำหนักใหม่ได้สัก 2 อาทิตย์จากนั้นรอไต่น้ำหนักใหม่ค่อยใส่อีกครั้ง -Reps ที่ 3+ ขึ้นไปสามารถใช้ขาส่งแรง Cheats 💥ช่วยได้ | H3: ไหล่
A4: 2 | B4: Lateral Raise | C4: ความหนัก 8/10 | D4: =IF(TRIM('(ถามตอบก่อนเล่น) ใส่ข้อมูลเฉพาะ'!$D$2)="5+","4", IF(TRIM('(ถามตอบก่อนเล่น) ใส่ข้อมูลเฉพาะ'!$D$2)="2-4","3-4", IF(TRIM('(ถามตอบก่อนเล่น) ใส่ข้อมูลเฉพาะ'!$D$2)="0-2","3","3"))) -> 3 | E4: 8–14 | F4: 2 | G4: -มือคว่ำเหมือนลินน้ำใส่แก้ว (อย่าให้ Forearm สูงเลยจากข้อศอก) -พยายามอย่าเหวี่ยงตัว ใช้ไหล่ยกเหมือนหมุนเฟืองที่ไหล่ ⚙️ 2ข้างขึ้นเป็นพอ -เอนตัวไปข้างหน้าเล็กน้อย ศอกล็อคประมาณ 80-90% ไม่ต้องยกเกินระดับไหล่ -เอนตัวไปข้างหน้าเล็กน้อย -Reps ที่ 10+ ไป Cheats 💥ช่วยได้โดยโยกหลังเล็กน้อย
A5: 3 | B5: Dumbbell Shoulder Press (ข้างละ) | C5: =ROUND((('(ถามตอบก่อนเล่น) ใส่ข้อมูลเฉพาะ'!D3*0.675)/2)*0.777,0) -> 34 | D5: =IF('(ถามตอบก่อนเล่น) ใส่ข้อมูลเฉพาะ'!$D$2="5+","4", IF('(ถามตอบก่อนเล่น) ใส่ข้อมูลเฉพาะ'!$D$2="2-4","3-4", IF('(ถามตอบก่อนเล่น) ใส่ข้อมูลเฉพาะ'!$D$2="0-2","3","3"))) -> 3 | E5: 8–12 | F5: 0.0625 | G5: -ใช้เข่าดัน Dumbbell ขึ้นมาทีละข้าง -ใครด้อยไหล่หน้าให้บีบศอกเข้าหากันเล็กน้อย (ศอกแคบยิ่งได้ไหล่หน้า ศอกกว้างยิ่งได้ไหล่รวม) -ถ้าไม่มีที่พิง ถ้าเล่นหนักอาจจะใช้แกนกลางลำตัวเยอะ แนะนำลดน้ำหนักแล้วเพิ่มจำนวนครั้งแทน -ถ้ารู้สึกว่าแรงตกเป็นเรืองปกติเพราะ Barbell overhead press กินแรงมาเรียบร้อยอาจจะลดเซ็ทเหลือ 3 ถ้ามันเล่นแทบไม่ออกจริงๆ
A6: 4 | B6: เลือกท่าใดก็ได้ (รอบหน้าสลับ) 🔄 | C6: =IFS( B6="เลือกท่าใดก็ได้ (รอบหน้าสลับ) 🔄","", B6="Front Raise -Wall Support","ความหนัก 6-7/10", B6="Front Raise","ความหนัก 7/10", B6="Single Arm Cable Front Raise","ความหนัก 6-7/10", B6="Straight bar Cable Front Raise","ความหนัก 7-8/10" ) | D6: =IF(B6="เลือกท่าใดก็ได้ (รอบหน้าสลับ) 🔄","", IF('(ถามตอบก่อนเล่น) ใส่ข้อมูลเฉพาะ'!$D$2="5+","4", IF('(ถามตอบก่อนเล่น) ใส่ข้อมูลเฉพาะ'!$D$2="2-4","3-4", IF('(ถามตอบก่อนเล่น) ใส่ข้อมูลเฉพาะ'!$D$2="0-2","3","3")))) | E6: =IFS( B6="เลือกท่าใดก็ได้ (รอบหน้าสลับ) 🔄","", B6="Front Raise -Wall Support","12-15", B6="Front Raise","10-12", B6="Single Arm Cable Front Raise","12-15", B6="Straight bar Cable Front Raise","8-10" ) | F6: =IF(B6="เลือกท่าใดก็ได้ (รอบหน้าสลับ) 🔄","", "1") | G6: =IFS( B6="เลือกท่าใดก็ได้ (รอบหน้าสลับ) 🔄","", B6="Front Raise -Wall Support","-เหมือน Front Raise ทุกอย่างให้นำหลังชิดกับกำแพงเผื่อให้ตัวไม่โยก -ศอกตรึงประมาณ 90-95% -ตอนออกแรงให้นึกถึงหมุนเฟืองขึ้นมา⚙️ยกได้จนถึงระยะคิ้วตัวเอง -สะบักกับก้น 4 จุดแตะกับกำแพงเหมือขาเก้าอี้ 🪑 -ถ้าเกิน 9+Reps แล้วไม่ไหว สามารถออกจากกำแพงแล้ว Cheats 💥ไ"&"ด้จนหมด", B6="Front Raise","-ศอกตรึงประมาณ 90-95% -ตอนออกแรงให้นึกถึงหมุนเฟืองขึ้นมา⚙️ยกได้จนถึงระยะคิ้วตัวเอง -ถ้าเกิน 9+Reps แล้วไม่ไหว สามารถออกจากกำแพงแล้ว Cheats 💥ได้จนหมด", B6="Single Arm Cable Front Raise","-เซ็ท cable ต่ำสุด -ศอกล็อคประมาณ 90-95% -ดึงขึ้นประมาณ ระดับสายตาหรือคิ้ว -ตอนลงให้ คุมแรงต้าน อย่าให้แผ่นเหล็กกระทบกัน -ถ้าเกิน 10 Reps แล้วไม่ไหว สามารถ Cheats 💥 เล็กน้อยได้เพื่อจบเซ็ต (ใช้อีกมือช่วย) -ข้อดีของการเล่นที่ละข้างคือจะ รู้หรือแก้สาเหตุกล้"&"ามเนื้อเรา Balance หรือไม่", B6="Straight bar Cable Front Raise","-เซ็ท cable ต่ำสุด -ศอกล็อคประมาณ 90-95% -ขึ้นประมาณ ระดับคิ้ว อย่าแกว่งตัวเหมือนที่ขุดน้ำมัน🛢️ -ถ้าเกิน 10 Reps แล้วไม่ไหว สามารถ Cheats 💥 เล็กน้อยได้เพื่อจบเซ็ต (โยกตัวเบาๆเอา) -สายซิ่งรอบจะไวกว่า single arm" )
A7: 5 Super Sets | B7: Machine Reverse Fly | C7: ความหนัก 7/10 | D7: 3 | E7: 10-14 | F7: 0.0625 | G7: -ตอนนั่งให้ก้นไม่ต้องชิดพนักพิงเบาะสุดให้ขยับมาข้างหน้าเหมือนใช้หลังบนพิงกับเบาะ -มือไม่ต้องกำหนัก หรือไม่ต้องกำเลยสัมผัสให้ได้เหมือนข้อต่อไหล่หลังทำงานเป็นเฟือง⚙️หมุนสุดระยะ -ปรับเบาะให้ระยะแขนขนานกับไหล่ กรณีที่เบาะปรับไม่ได้ ให้ยืนย่อหรือเล่นได้ -เก็บ Tension หรือความตรึงกล้ามเนื้อตลอดเวลา (อย่าให้มีเสียงเหล็กจากเครื่องกระทบกัน) -เมื่อแรงหมดให้ขยับก้นขยับไปชิดกับเบาะและเอนตัวมาข้างหน้าเล็กน้อยCheats 💥 ครั้งที่ 8+ ขึ้นไป ระวังเจ็บพอ
B8: Abs Cable Crunch | C8: ความหนัก 6-7/10 | D8: 3 | E8: 15-30 | F8: 0.0625 | G8: -เป็น 1 ในน้อยท่าที่ต้องหลังค่อมตอนเล่น (เพื่อให้กล้ามเนื้อท้องเกร็งตลอดเวลา) -แนะนำให้เพื่อนดูฟรอมส์หรือถ่ายวีดีโอตัวเองอย่าให้ก้นเคลื่อนที่ไปมา -แนะนำใช้ Single Handle Cable กรณีที่ไม่มีก็ใช้ Rope -ถ้ามาถูกทางจากจำนวนครั้งที่ 30 จะค่อยๆ ลดเป็น 25,20 ลงมาเรื่อยๆแต่ไม่ควรต่ำกว่า 7 ครั้ง | H8: ท้อง
A9: 6 | B9: Leg Raise Dip Station | C9: ความหนัก 7/10 | D9: 4 | E9: 15-20 | F9: 0.041666667 | G9: -ระยะเข่างอได้นิดหน่อยถ้าขาตรึงสุดระยะ Hip Flexor จะทำงานหนักแต่ถ้าอยากได้ก็โอเค... -ตอนลงให้ลงเกร็งตลอดเวลาอย่า Swing ไปมาไม่งั้นจะไม่ค่อยได้อะไร เล่นช้าๆ 1,2 ตอนลง 1,2,3 -เบาไปก็เอาดัมเบลมาหนีบที่เท้า ไม่ต้องหนักแต่ต้านช้าๆ
A10: โปรแกรมเป็นเพียงแนวทาง ปรับ Volume ตามสภาพร่างกายและการฟื้นตัวของตัวเองเป็นหลัก อย่าฝืนซ้อมหากร่างกายส่งสัญญาณว่าพักไม่พอ | H10: License - Baygeta
A11: พักตามความพร้อมของร่างกาย (แนะนำเล่นต่อเนื่อง 4–6 วัน) แล้วนับต่อจากวันที่เล่นล่าสุด | H11: สามารถคัดลอก แก้ไข และแจกจ่ายไฟล์นี้ได้อิสระ ห้ามนำไปขายหรือใช้เพื่อการค้า

Sheet ขา A
A1: No. | B1: Exercise | C1: Weight(Kg) | D1: Sets | E1: Reps | F1: Rest | G1: Tips | H1: Group Muscle
A2: ลำดับ | B2: ชื่อท่า | C2: นน. | D2: เซต | E2: ครั้ง | F2: พัก | G2: แนะนำ | H2: กลุ่มกล้ามเนื้อ
A3: 1 | B3: Squat Free Weight | C3: =ROUND('(ถามตอบก่อนเล่น) ใส่ข้อมูลเฉพาะ'!D5* IF(TRIM('(ถามตอบก่อนเล่น) ใส่ข้อมูลเฉพาะ'!$D$2)="5+",0.7, IF(TRIM('(ถามตอบก่อนเล่น) ใส่ข้อมูลเฉพาะ'!$D$2)="2-4",0.65, IF(TRIM('(ถามตอบก่อนเล่น) ใส่ข้อมูลเฉพาะ'!$D$2)="0-2",0.55))),0) -> 0 | D3: 4 | E3: 8–10 | F3: =IF(TRIM('(ถามตอบก่อนเล่น) ใส่ข้อมูลเฉพาะ'!$D$2)="5+","4", IF(TRIM('(ถามตอบก่อนเล่น) ใส่ข้อมูลเฉพาะ'!$D$2)="2-4","3", IF(TRIM('(ถามตอบก่อนเล่น) ใส่ข้อมูลเฉพาะ'!$D$2)="0-2","2","2"))) -> 2 | G3: -ยืดวรอมประมาณ 5-15 นาทีก่อนเล่น ก่อนจะเล่นแนะนำไต่น้ำหนัก 40% 60% 80% => น้ำหนักจริง -น้ำหนักที่คำนวณมาเป็นน้ำหนักที่ระยะออกแรงขึ้นลงจนสุดกรณีที่ลงประมาณ 90° ให้เพิ่มน้ำหนัก 20-30% -ใครต้องการเปลี่ยนฟอร์ม Squat เป็นลงสุด (ต้องไต่น้ำหนักใหม่เริ่มจากเบา ไม่งั้นเสี่ยงเจ็บ) -ถ้ามีเข็มขัดใส่บล็อคหลังทุกครั้งที่พยายามขึ้นน้ำหนักใหม่ได้สัก 2 อาทิตย์จากนั้นรอไต่น้ำหนักใหม่ค่อยใส่อีกครั้ง -มือใหม่ให้ถ่ายคลิปตัวเอง หรือให้เพื่อนช่วยดูฟรอมส์ | H3: ขา
A4: 2 | B4: Leg Extension | C4: ความหนัก 7/10 | D4: 4 | E4: 46364 | F4: 2 | G4: -ก่อนจะเล่นแนะนำไต่น้ำหนัก 40%,70% => น้ำหนักจริง -ขึ้นสุด เหยียดขาตึง อย่าเร่งความเร็วถ้าไม่กรณี 10 ครั้งขึ้นไป+ -ตอนลงอย่าลงจนเครื่องเกิดเสียงเหล็กกระทบ ให้เกร็งแรงต้านไว้ตลอดเวลาเผื่อให้กล้ามเนื้อทำงานตลอด -จับที่จับแล้วดึงอย่าให้ตัวลอย ก้นต้องติดกับเครื่องตลอดเวลา ไม่งั้นระยะสั้น,ยาว อาจบาดเจ็บเอาได้
A5: 3 | B5: เลือกท่าใดก็ได้ (รอบหน้าสลับ) 🔄 | C5: =IF(B5="เลือกท่าก่อนเล่น","", IF(B5="Lying Leg Curl","ความหนัก 7/10", IF(B5="Seated Leg Curl","ความหนัก 7/10",""))) | D5: =IF(B5="เลือกท่าก่อนเล่น","", IF(B5="Lying Leg Curl","4", IF(B5="Seated Leg Curl","4",""))) | E5: =IF(B5="เลือกท่าก่อนเล่น","", IF(B5="Lying Leg Curl","8-12", IF(B5="Seated Leg Curl","8-12",""))) | F5: =IF(B5="เลือกท่าก่อนเล่น","", IF(B5="Lying Leg Curl","1", IF(B5="Seated Leg Curl","1",""))) | G5: =IF(B5="เลือกท่าใดก็ได้ (รอบหน้าสลับ) 🔄", "**โปรดเลือกท่าก่อนเล่นให้สลับกันแต่ละครั้ง ตัวอย่าง : รอบนี้เล่น Lying รอบหน้าเล่น Seated แทน ส่วนตัวรู้สึก Laying Leg Curl โดนกว่า**", IF(B5="Lying Leg Curl", "-ระยะออกแรงให้ออกแรงจนเครื่องแตะก้นเราให้ได้ อย่าให้เครื่องกระทบกันมีแรงต้านเสมอ -ตอนลงอย่าลงจนเครื่องเกิดเสียง ให้เกร็งแรงต้านไว้ตลอดเวลาเผื่อให้กล้ามเนื้อทำงานตลอด -ให้คิดสะว่าเหมือนเราเล่นท่า Bicep Preacher Curl หลังขาเราคือหน้าแขนหมุนเฟือง ⚙️ แค่นั้นเ"&"ลยจริงๆ -พยายามอย่าให้ก้นเคลื่อนที่ในขณะเล่น ระยะยาวจะปวดหลังได้ จับด้ามจับไม่ก็ใช้แขนล็อคให้นิ่งๆ -ส่วนตัวชอบ Lying มากกว่าไม่มีการกดทับกล้ามเนื้อแต่แอบหน้ามืดแนะนำพอถึง ขา B ให้สลับไปมา กรณีเครื่องมีแค่เครื่องเดียวก็เล่นได้ไม่เสียหาย", IF(B5="Seated Leg Curl", "-ระยะออกแรงให้ออกแรงจนเครื่องแตะก้นเราให้ได้ อย่าให้เครื่องกระทบกันมีแรงต้านเสมอ -ตอนลงอย่าลงจนเครื่องเกิดเสียง ให้เกร็งแรงต้านไว้ตลอดเวลาเผื่อให้กล้ามเนื้อทำงานตลอด -ให้คิดสะว่าเหมือนเราเล่นท่า Bicep Preacher Curl หลังขาเราคือหน้าแขนหมุนเฟือง ⚙️ แค่นั้นเ"&"ลยจริงๆ -พยายามอย่าให้ก้นลอย ดึงตัวเองให้ติดกับเบาะเสมอ ลอยเมื่อไหร่สะสมแต้มหลังเดาะ", ""))) -> **โปรดเลือกท่าก่อนเล่นให้สลับกันแต่ละครั้ง ตัวอย่าง : รอบนี้เล่น Lying รอบหน้าเล่น Seated แทน ส่วนตัวรู้สึก Laying Leg Curl โดนกว่า**
A6: 4 Super Sets | B6: Abduction | C6: ความหนัก 7/10 | D6: =IF(TRIM('(ถามตอบก่อนเล่น) ใส่ข้อมูลเฉพาะ'!$D$2)="5+","4", IF(TRIM('(ถามตอบก่อนเล่น) ใส่ข้อมูลเฉพาะ'!$D$2)="2-4","3-4", IF(TRIM('(ถามตอบก่อนเล่น) ใส่ข้อมูลเฉพาะ'!$D$2)="0-2","3","3"))) -> 3 | E6: 12-15 | F6: 0.0625 | G6: -เซ็ทเครื่องความยืดหยุ่นของขาหนีบเรา 90% (ยิ่งเยอะยิ่งดี) -พยายามแค่ใช้ปลายเท้าแตะกับตัวเครื่องจะทำให้ออกแรงจากก้นโดนกว่า -เอนตัวไปข้างหน้าเอามือจับกับเครื่องเพื่อให้โดนก้นกว่า -ให้ลองใช้ปลายเท้าแตะกับเครื่องไว้แค่ประคองเฉยๆ จากนั้นออกแรงถ้ารุ้สึกหนักขึ้นแสดงว่ามาถูกทาง -พยายามสลับท่าเปิด ตัวอย่าง : Abduction เปิด รอบหน้าให้เปิดด้วยท่า Adduction แทน
B7: Adduction | C7: ความหนัก 7/10 | G7: -เซ็ทเครื่องความยืดหยุ่นของขาหนีบเรา 90% -พยายามแค่ใช้ปลายเท้าแตะกับตัวเครื่องจะทำให้ออกแรงจากก้นโดนกว่า -ขยับเข่าหามุมที่ออกแรงแล้วโดนขาหนีบที่สุด -ให้ลองใช้ปลายเท้าแตะกับเครื่องไว้แค่ประคองเฉยๆ จากนั้นออกแรงถ้ารุ้สึกหนักขึ้นแสดงว่ามาถูกทาง -จะตัวตรงจะพิงก็ได้ ไม่ค่อยต่างเท่าไหร่ (ส่วนตัว)
A8: 5 | B8: Seated Calf Raises | C8: ความหนัก 7/10 | D8: 4 | E8: 15-20 | F8: 1 | G8: -ก่อนจะเล่นแนะนำไต่น้ำหนัก 70% => น้ำหนักจริง -ลงให้ลึกสุดระยะน่อง -ตอนขึ้นเกร็งค้างไว้ประมาณ 1.5 - 2 วินาที -นั่งนิ่งๆฟิลแค่น่องอย่างเดียว (อย่าโยกตัวเขย่าเหมือนเล่นม้านั่งเด็กมันดูติ๊งต๊อง🤡)
A9: 6 | B9: Dumbell Bicep Curl | C9: ความหนัก 7/10 | D9: =IF(TRIM('(ถามตอบก่อนเล่น) ใส่ข้อมูลเฉพาะ'!$D$2)="5+","4", IF(TRIM('(ถามตอบก่อนเล่น) ใส่ข้อมูลเฉพาะ'!$D$2)="2-4","3-4", IF(TRIM('(ถามตอบก่อนเล่น) ใส่ข้อมูลเฉพาะ'!$D$2)="0-2","3","3"))) -> 3 | E9: 10 | F9: 2 | G9: -ก่อนจะเล่นแนะนำไต่น้ำหนัก 40% 60% 80% => น้ำหนักจริง -หลังตรงจนครั้งที่ 8ครั้ง+ สามารถ Cheats 💥 โยกได้นิดหน่อย(ระวังปวดหลัง) -ฟรอมส์จะเล่นดามหน้าขาตัวเองก็ได้ จะยืนปกติก็ได้สลับไปมาในรอบถัดไป | H9: หน้าแขน
A10: 7 | B10: Concentration Curl | C10: ความหนัก 7/10 | D10: =IF(TRIM('(ถามตอบก่อนเล่น) ใส่ข้อมูลเฉพาะ'!$D$2)="5+","4", IF(TRIM('(ถามตอบก่อนเล่น) ใส่ข้อมูลเฉพาะ'!$D$2)="2-4","3-4", IF(TRIM('(ถามตอบก่อนเล่น) ใส่ข้อมูลเฉพาะ'!$D$2)="0-2","3","3"))) -> 3 | E10: 15 | F10: 2 | G10: -ลดน้ำหนักที่เล่นจากท่า Dumbell Bicep Curl ก่อนหน้านี้ไป 30-40% -ดามแขนด้วยขาตัวเอง แล้วหมุนเฟือง⚙️หน้าแขนของเราที่ดามไว้ โดยให้ศอกขยับน้อยที่สุด -เล่นไปปอดจะไม่แตกแต่กล้ามเนื้อแทบจะขยับไม่ได้ Cheats 💥โดยให้ใช้อีกมือเซฟโดยการใช้แค่ สองนิ้วช่วยพอ ช่วยได้ก็ต่อเมื่อครั้งที่ 8+ (ถ้าใช้มากกว่าสองนิ้วแล้วแนะนำให้ลด น้ำหนักเพราะยังหนักไป)
A11: โปรแกรมเป็นเพียงแนวทาง ปรับ Volume ตามสภาพร่างกายและการฟื้นตัวของตัวเองเป็นหลัก อย่าฝืนซ้อมหากร่างกายส่งสัญญาณว่าพักไม่พอ | H11: License - Baygeta
A12: พักตามความพร้อมของร่างกาย (แนะนำเล่นต่อเนื่อง 4–6 วัน) แล้วนับต่อจากวันที่เล่นล่าสุด | H12: สามารถคัดลอก แก้ไข และแจกจ่ายไฟล์นี้ได้อิสระ ห้ามนำไปขายหรือใช้เพื่อการค้า

Sheet อก B
A1: No. | B1: Exercise | C1: Weight(Kg) | D1: Sets | E1: Reps | F1: Rest | G1: Tips | H1: Group Muscle
A2: ลำดับ | B2: ชื่อท่า | C2: นน. | D2: เซต | E2: ครั้ง | F2: พัก | G2: แนะนำ | H2: กลุ่มกล้ามเนื้อ
A3: 1 | B3: Incline Bench Press | C3: =FLOOR('(ถามตอบก่อนเล่น) ใส่ข้อมูลเฉพาะ'!D3*0.7,2.5) -> 90 | D3: =IF(TRIM('(ถามตอบก่อนเล่น) ใส่ข้อมูลเฉพาะ'!$D$2)="5+","4", IF(TRIM('(ถามตอบก่อนเล่น) ใส่ข้อมูลเฉพาะ'!$D$2)="2-4","3-4", IF(TRIM('(ถามตอบก่อนเล่น) ใส่ข้อมูลเฉพาะ'!$D$2)="0-2","3","3"))) -> 3 | E3: 7–10 | F3: 3-5 (ตามฟิล) | G3: -น้ำหนักที่เล่นได้จะต่ำกว่าท่า Bench Press ประมาณ 10-25% -ก่อนจะเล่นแนะนำไต่น้ำหนัก 40% 60% 80% => น้ำหนักจริง -ขึ้นสุดลงสุดแตะลิ้นปี่ -จำนวน Rep จะค่อยๆ ลดลงไม่ต้องตกใจ แต่อย่าต่ำกว่า 6 เป็นพอ -แนะนำหาคนเซฟจะปลอดภัยกับ Push ได้สุดมากๆ (ส่วนใครไม่เคยเล่น รูปแบบstrength คือ 5 ครั้ง แนะนำให้มีอายุกล้ามเนื้อสัก 3-5 เดือน+ ถึงจะค่อยเล่นครับ) | H3: อก
A4: 2 | B4: Chest Press Machine | C4: ความหนัก 8/10 | D4: =IF(TRIM('(ถามตอบก่อนเล่น) ใส่ข้อมูลเฉพาะ'!$D$2)="5+","4", IF(TRIM('(ถามตอบก่อนเล่น) ใส่ข้อมูลเฉพาะ'!$D$2)="2-4","4", IF(TRIM('(ถามตอบก่อนเล่น) ใส่ข้อมูลเฉพาะ'!$D$2)="0-2","3","3"))) -> 3 | E4: 8–14 | F4: 2 | G4: -ก่อนจะเล่นแนะนำไต่น้ำหนัก 75% => น้ำหนักจริง -เล่นเกือบสุดระยะของศอก 95% (ไม่ต้องล็อคศอก ไม่งั้นระยะยาวเอากระดูกมาหักเล่นเจ็บกันตามสภาพ) -เครื่องแต่ละเครื่องจะไม่เหมือนกันทั้งมุมนั่งหรือความสูงเบา ให้จำลองสะเหมือนมีบาร์ Bench Press กำลังจะแตะอกเรา ยิ่งเครื่องไหนลงได้ลึกทะลุอกเราได้ยิ่งดีแต่การลงแนะนำให้ลงไม่ต้องลึกเวอร์จนทำให้ไหล่เข้ามาทำภาระแทน
A5: 3 | B5: เลือกท่าใดก็ได้ (รอบหน้าสลับ) 🔄 | C5: =IFS( TRIM(B5)="เลือกท่าก่อนเล่น","", TRIM(B5)="Assit Dips","ความหนัก 7-8/10", TRIM(B5)="Dips น้ำหนักตัว",'(ถามตอบก่อนเล่น) ใส่ข้อมูลเฉพาะ'!D6, TRIM(B5)="Dips ถ่วง","ความหนัก 9/10", TRIM(B5)="Cable Dips","ความหนัก 7-8/10", TRUE,"" ) | D5: =IF(B5="เลือกท่าก่อนเล่น","", IF(C5="-","", IF('(ถามตอบก่อนเล่น) ใส่ข้อมูลเฉพาะ'!$D$2="5+","4-5", IF('(ถามตอบก่อนเล่น) ใส่ข้อมูลเฉพาะ'!$D$2="2-4","4-5", IF('(ถามตอบก่อนเล่น) ใส่ข้อมูลเฉพาะ'!$D$2="0-2","4","4-5"))))) | E5: =IFS( B5="เลือกท่าใดก็ได้ (รอบหน้าสลับ) 🔄","", B5="Assit Dips","10-12", B5="Dips น้ำหนักตัว","จนหมด", B5="Dips ถ่วง","10", B5="Cable Dips","12-15" ) | F5: =IFS( B5="เลือกท่าใดก็ได้ (รอบหน้าสลับ) 🔄","", B5="Assit Dips","1:30", B5="Dips น้ำหนักตัว","1:30", B5="Dips ถ่วง","3:00", B5="Cable Dips","1:30" ) | G5: =IFS( B5="Assit Dips", "-แนะนำในการฝึกอกหามุมที่สามารถออกแรงให้เหมือนมุม Dip ให้ได้ -หลักการง่ายๆยิ่งตัวตั้งตรงมากเท่าไหร่อาจจะออกแรงจากหลังแขนมากเท่านั้น แนะนำให้เอนตัวไปข้างหน้านิดหน่อย -ใครศอกบาดเจ็บอยู่หนีไป Cable ได้เลยจนกว่าจะหายค่อยเล่นท่านี้ -ใครที่ dip เกิน 8 ครั้งแล้วไ"&"ม่ต้องเล่นท่านี้แล้วให้เลือกท่าอื่นแทน", B5="Dips น้ำหนักตัว", "-ใครรู้สึกปวดข้อศอกหรือข้อต่อบาดเจ็บอยู่หนีไปเล่นท่าอื่นได้เลย -Dip ให้เอียงตัวไปข้างหน้าเล็กน้อย45° เพื่อให้กล้ามเนื้ออกทำงานได้เต็มมากขึ้น -เราโฟกัสอกล่าง ให้ออกแรงผ่านอกก่อนหลังแขนเสมอ", B5="Dips ถ่วง", "-ใครรู้สึกปวดข้อศอกหรือข้อต่อบาดเจ็บอยู่หนีไปเล่นท่าอื่นได้เลย -วรอมอัพโดยการดันกับน้ำหนักตัวก่อน=>60%=>80=>เล่นจริง -หากยังดึงข้อไม่ถึง 12 ครั้งแนะนำให้ดึงข้อน้ำหนักตัวฟรอมส์ดีๆก่อนจนครบ 20 ครั้งแล้ว", B5="Cable Dips", "-ถ้าคุกเข่าเล่นให้เซ็ท Cable ประมาณระดับอกบนหรือคอ -กรณีที่ยืนอยู่เท้าข้างนึงจะนำอีกข้างแนะนำให้ สลับขากันแต่ละเซ็ท (แก้ Balance ระยะยาว ) -ศอกงอสุดระยะที่ 90 พอสุดระยะมือเราจะใกล้ๆกับหน้าอกของเรา -ออกแรงจากอกก่อนเสมอหลังแขนอะไรมาทีหลังนอกสะจาก reps 8+ ใช"&"้ cheats ได้", TRUE,"" )
A6: 4 | B6: เลือกท่าตามมัดที่ด้อย 🎯 ก่อนเล่น | C6: =IFS( B6="Cable Fly Incline (อกบน)","ความหนัก 7/10", B6="Cable Fly (อกกลาง)","ความหนัก 7/10", B6="Cable Fly Decline (อกล่าง)","ความหนัก 7/10", B6="Dumbbells Incline Fly (อกบน)","ความหนัก 6-7/10", B6="Dumbbells Fly (อกกลาง)","ความหนัก 6-7/10", B6="Machine Fly (อกกลาง)","ความหนัก 8/10", B6="เลือกท่าตามมัดที่ด้อย 🎯 ก่อนเล่น","" ) | D6: =IF(B6="เลือกท่าตามมัดที่ด้อย","", IF(C6="-","", IF('(ถามตอบก่อนเล่น) ใส่ข้อมูลเฉพาะ'!$D$2="5+","4", IF('(ถามตอบก่อนเล่น) ใส่ข้อมูลเฉพาะ'!$D$2="2-4","3-4", IF('(ถามตอบก่อนเล่น) ใส่ข้อมูลเฉพาะ'!$D$2="0-2","4","3"))))) | E6: =IFS( B6="เลือกท่าตามมัดที่ด้อย 🎯 ก่อนเล่น","", B6="Cable Fly Incline (อกบน)","10-12", B6="Cable Fly (อกกลาง)","10-12", B6="Cable Fly Decline (อกล่าง)","10-12", B6="Dumbbells Incline Fly (อกบน)","8-12", B6="Dumbbells Fly (อกกลาง)","8-12", B6="Machine Fly (อกกลาง)","10-12" ) | F6: =IFS( B6="Cable Fly Incline (อกบน)","1", B6="Cable Fly (อกกลาง)","1", B6="Cable Fly Decline (อกล่าง)","1", B6="Dumbbells Incline Fly (อกบน)","1", B6="Dumbbells Fly (อกกลาง)","1", B6="Machine Fly (อกกลาง)","1:30", B6="เลือกท่าตามมัดที่ด้อย 🎯 ก่อนเล่น","" ) | G6: =IFS( B6="Cable Fly Incline (อกบน)","-เหมาะสำหรับอกบนด้อยโดนไหล่แซง -เล่นแบบไขว้แขน (Cross) สลับทุกเซ็ท เช่น เซ็ทแรกซ้ายทับขวา เซ็ทต่อไปขวาทับซ้าย -ท่ายืนเลือกแบบที่มั่นคง จะยืนปกติหรือยืนไขว้ขาก็ได้ และสลับขาทุกเซ็ทเหมือนแขน (ส่วนตัวคุกเข่า) สลับไปมาจะได้ช่วยเรื่อง Muscle Balance", B6="Cable Fly (อกกลาง)","เป็นมุมปกติไว้ฟามกล้าม ถ้าอกดูสมส่วนอยู่แล้วก็สแปมอันนี้แหละ 70% -เล่นสลับกัน แบบมือไขว้ ถ้าข้างซ้ายอยู่เหนือมือขวา เซ็ทหน้ามือขวาอยู่เหนือซ้าย cross ไขว้สลับกัน -ขาจะยืน ท่าไหนมุมไหนก็ได้ขอให้มั่นคง ถ้ายืนขาไขว้ก็เช่นเดียวกันกับแขน สลับกันไปมาทุกเซ็ท การ"&"เล่นสลับไปมาจะแก้ Muscle Balance แล้วระยะมันจะสุดกว่าการเล่นมือชนกัน (ระยะ+balance)", B6="Cable Fly Decline (อกล่าง)","-(ส่วนตัวไม่ค่อยเล่น Decline) -เล่นสลับกัน แบบมือไขว้ ถ้าข้างซ้ายอยู่เหนือมือขวา เซ็ทหน้ามือขวาอยู่เหนือซ้าย cross ไขว้สลับกัน -ขาจะยืน ท่าไหนมุมไหนก็ได้ขอให้มั่นคง ถ้ายืนขาไขว้ก็เช่นเดียวกันกับแขน สลับกันไปมาทุกเซ็ท การเล่นสลับไปมาจะแก้ Muscle Balance แล"&"้วระยะมันจะสุดกว่าการเล่นมือชนกัน (ระยะ+balance)", B6="Dumbbells Incline Fly (อกบน)","-ใครด้อยอกบนควรหยิบท่านี้ -ใช้เข่า Take ทุกครั้งก่อนเริ่มเล่น -ปรับเบาะประมาณ 45° -ตอนลงให้ยืดอกเต็มช่วง และตอนขึ้นบีบอกค้างเล็กน้อย -อย่าเอาดัมเบลชนกัน ให้บีบอกแทน", B6="Dumbbells Fly (อกกลาง)","-เน้นอกกลาง เป็นมุมมาตรฐานของ Fly -ใช้เข่า Take ทุกครั้งก่อนเริ่มเล่น -ตอนออกแรงให้บีบอกจนสุดจากนั้นระยะแขน ดันเมื่อ movement อกขยับเต็มที่แล้ว -(ส่วนตัวไม่ค่อยชอบเล่นท่านี้เท่าไหร่ ปวดข้อมือชิพหายพอเล่นหนักๆ จะเล่นอกเสือกโดนข้อมือเจริญพรนามัสเต)", B6="Machine Fly (อกกลาง)","-ปรับระยะมุมด้ามจับให้เลยศอกเล็กน้อย (ตามความยืดหยุ่น) -ตอนเล่นให้นึกถึง กล้ามปู🦀 ที่หนีบ หมุนเฟือง⚙️ ในหน้าอกเข้าหากัน -ช่วงศอกไม่ต้องตึง 100% งอเล็กน้อย 80-90% -(ส่วนตัว50% จะเล่นท่านี้ ถ้าเล่นไปแล้วแนะนำให้สลับไปเล่นกับ cable รอบหน้า)", B6="เลือกท่าตามมัดที่ด้อย 🎯 ก่อนเล่น","" )
A7: 5 | B7: Close Grip Bench Press | C7: =MROUND('(ถามตอบก่อนเล่น) ใส่ข้อมูลเฉพาะ'!D4*0.65,2.5) -> 0 | D7: =IF('(ถามตอบก่อนเล่น) ใส่ข้อมูลเฉพาะ'!$D$2="5+",4, IF('(ถามตอบก่อนเล่น) ใส่ข้อมูลเฉพาะ'!$D$2="2-4","3-4", IF('(ถามตอบก่อนเล่น) ใส่ข้อมูลเฉพาะ'!$D$2="0-2","3-4","3"))) -> 3-4 | E7: 46364 | F7: 2 | G7: -จับแคบให้ศอกเหมือนพุ่งไปด้านหน้าแถวๆท้องข้าง (ไม่ใช่ออกข้างแบบ Bench Press) -ให้จับข้อมือเป็นเส้นตรง II (ถ้าจับแคบเกิน ข้อมือจะทำงานหนักเหมือน /I\ งอตลอดเวลาซึ่งอาจจะเจ็บได้) ส่วนถ้าจับกว้างเกินแน่นอนยิ่งไปโดนอกและไหล่กลายเป็น Bench press -ถ้านี้แนะนำถ้ามาถูกทางช่วงจะหมดแรงบาร์แทบจะทับได้เลยแนะนำหาคนเซฟก่อนช่วงแรกๆ | H7: หลังแขน
A8: 6 | B8: Dumbell Tricep Extension One Hand | C8: =IF('(ถามตอบก่อนเล่น) ใส่ข้อมูลเฉพาะ'!$D$2="5+","ความหนัก 9-10/10", IF('(ถามตอบก่อนเล่น) ใส่ข้อมูลเฉพาะ'!$D$2="2-4","ความหนัก 8/10", IF('(ถามตอบก่อนเล่น) ใส่ข้อมูลเฉพาะ'!$D$2="0-2","ความหนัก 7/10", "ความหนัก 9-10/10"))) -> ความหนัก 7/10 | D8: =IF(TRIM('(ถามตอบก่อนเล่น) ใส่ข้อมูลเฉพาะ'!$D$2)="5+","4", IF(TRIM('(ถามตอบก่อนเล่น) ใส่ข้อมูลเฉพาะ'!$D$2)="2-4","3-4", IF(TRIM('(ถามตอบก่อนเล่น) ใส่ข้อมูลเฉพาะ'!$D$2)="0-2","3","3"))) -> 3 | E8: 7–10 | F8: 2 | G8: -ก่อนจะเล่นแนะนำไต่น้ำหนัก 40% 60% 80% => น้ำหนักจริง (ไม่งั้นเระยะยาวจ็บการันตี) -แขนข้างที่เล่นองศาตรง จากนั้นลงให้แตะไหล่อีกข้าง (แต่เลยมาด้านหลังเล็กน้อย) -อีกมือคอยซัพพรอต์จากที่บริเวณโฟร์อามกับข้อศอกค่อยๆเซฟหลังจากครั้งที่ 8+ Cheats 💥ได้ใช้อีกมือช่วย -แนะนำให้เล่นมองกระจก มุมข้าง และตรงหน้า
A9: 7 | B9: Tricep Cable Kickback | C9: ความหนัก 7/10 | D9: =IF('(ถามตอบก่อนเล่น) ใส่ข้อมูลเฉพาะ'!$D$2="5+","4", IF('(ถามตอบก่อนเล่น) ใส่ข้อมูลเฉพาะ'!$D$2="2-4","3", IF('(ถามตอบก่อนเล่น) ใส่ข้อมูลเฉพาะ'!$D$2="0-2","3","3"))) -> 3 | E9: 12–15 | F9: 1 | G9: -เซ็ต Cable ระดับต่ำสุดหรือหน้าแข้ง ถอดด้ามจับออก เหลือลูกยางกันกระแทก แล้วก็กำไอลูกนั้นแหละ -ช่วงต้นแขนอยู่นิ่ง ให้ระยะองศาแขนขนานกับพื้นหรือมากกว่า 180+° s หรือจะก้มต่ำสุดๆให้ระยะออกแรงแรกยากสุด -เล่นทีละข้างจะทำให้กล้ามเรา Balance มากขึ้น และปรับความต่างของแขนซ้ายขวา -กรณีไม่ถึง Cheats 💥โดยใช้อีกมือเซฟ แต่อย่าช่วยเยอะจ่ายแรงพอควร (ควรเซฟครั้งที่ 10Reps+) -ตอนวางระวังลูกยางแดกนิ้ว
A10: โปรแกรมเป็นเพียงแนวทาง ปรับ Volume ตามสภาพร่างกายและการฟื้นตัวของตัวเองเป็นหลัก อย่าฝืนซ้อมหากร่างกายส่งสัญญาณว่าพักไม่พอ | H10: License - Baygeta
A11: พักตามความพร้อมของร่างกาย (แนะนำเล่นต่อเนื่อง 4–6 วัน) แล้วนับต่อจากวันที่เล่นล่าสุด | H11: สามารถคัดลอก แก้ไข และแจกจ่ายไฟล์นี้ได้อิสระ ห้ามนำไปขายหรือใช้เพื่อการค้า

Sheet หลัง B
A1: No. | B1: Exercise | C1: Weight(Kg) | D1: Sets | E1: Reps | F1: Rest | G1: Tips | H1: Group Muscle
A2: ลำดับ | B2: ชื่อท่า | C2: นน. | D2: เซต | E2: ครั้ง | F2: พัก | G2: แนะนำ | H2: กลุ่มกล้ามเนื้อ
A3: 1 | B3: เลือกท่าใดก็ได้ (รอบหน้าสลับ) 🔄 | C3: =IFS( B3="เลือกท่าใดก็ได้ (รอบหน้าสลับ) 🔄","", B3="Pull-up Wide Grip ถ่วงน้ำหนัก", IF( MROUND(('(ถามตอบก่อนเล่น) ใส่ข้อมูลเฉพาะ'!D6*('(ถามตอบก่อนเล่น) ใส่ข้อมูลเฉพาะ'!D8/30))*0.6,5)<=10, 0, MROUND(('(ถามตอบก่อนเล่น) ใส่ข้อมูลเฉพาะ'!D6*('(ถามตอบก่อนเล่น) ใส่ข้อมูลเฉพาะ'!D8/30))*0.6,5) ), B3="Pull-up Wide Grip","น้ำหนักตัว", B3="Lat Pulldown","ความหนัก 7-8/10" ) | D3: =IF(B3="เลือกท่าใดก็ได้ (รอบหน้าสลับ) 🔄","", IF('(ถามตอบก่อนเล่น) ใส่ข้อมูลเฉพาะ'!$D$2="5+",5, IF('(ถามตอบก่อนเล่น) ใส่ข้อมูลเฉพาะ'!$D$2="2-4","4", IF('(ถามตอบก่อนเล่น) ใส่ข้อมูลเฉพาะ'!$D$2="0-2","3-4","3-4")))) | E3: =IFS( B3="เลือกท่าใดก็ได้ (รอบหน้าสลับ) 🔄","", B3="Pull-up Wide Grip ถ่วงน้ำหนัก",IF(C3=0,"8-15","6-10"), B3="Lat Pulldown","7-10", B3="Assit Pullup","8-12" ) | F3: =IFS( B3="เลือกท่าใดก็ได้ (รอบหน้าสลับ) 🔄","", B3="Pull-up Wide Grip ถ่วงน้ำหนัก",IF(C3=0,"1:30","2-3"), B3="Lat Pulldown","2-3", B3="Assit Pullup","1:30" ) | G3: =IFS( B3="เลือกท่าใดก็ได้ (รอบหน้าสลับ) 🔄","", AND(B3="Pull-up Wide Grip ถ่วงน้ำหนัก",C3>=10), "-ดึงข้อด้วยน้ำหนักตัวเองก่อนสัก 8-10 ครั้งจากนั้นไต่น้ำหนักวรอม 50% → 80% → น้ำหนักจริง"&CHAR(10)& "-Grip แนะนำให้เล่นสลับกัน closed หรือ Wideในแต่ละรอบฝึก "&CHAR(10)& "-กรณีเป็นแผ่น Plate แนะนำถ่วงให้แผ่นเหล็กมาอยู่ที่ขาหลังเหมือนเป็นจานแล้วรองด้วยขาจะช่วยทำให้นิ่งกว่า", B3="Pull-up Wide Grip ถ่วงน้ำหนัก", "-ก่อนจะดึงข้อน้ำหนักตัวเองแนะนำให้ warm up กับ Lat pulldown ก่อน ไล่จาก 50% → 80% → น้ำหนักตัว"&CHAR(10)& "-ถ้ายังดึงไม่เลยแนะนำให้เลือกท่า Lat Pulldown หรือ Assit Pullup", B3="Lat Pulldown", "-ก่อนเล่นให้ไต่ น้ำหนัก 50%,70%,80%→ น้ำหนักจริง"&CHAR(10)& "-ให้หลังทำงานก่อนแขนเสมอ"&CHAR(10)& "-ถ้าแรงหมดสามารถ Cheats 💥โยกตัวช่วยได้หลัง rep 7+ (อย่าโยกมากระวังเจ็บ)", B3="Assit Pullup", "-หลังไม่ค่อม ตอนดึงให้คิดว่ากำลังดึงข้อจริง"&CHAR(10)& "-ขึ้นสุดให้หลังทำงานเต็มระยะ"&CHAR(10)& "-ถ้าเครื่องกระตุกหรือไม่ลื่น เปลี่ยนเครื่องได้" ) | H3: หลัง
A4: 2 | B4: Dumbell Row | C4: ความหนัก 8-9/10 | D4: 4-5 | E4: 7–10 | F4: 2 | G4: -จะปรับเบาะตรง,เอียง 45° ได้หมด (พยายามสลับกันรอบหน้า) -แนะนำให้ลองดึงแบบผิดๆโดยใช้หน้าแขนเต็มๆดูก่อน จากนั้นถอดความรู้สึกที่ใช้หน้าแขนแล้วดึงให้ศอกเลยหลัง -เริ่มจากฝั่งที่ด้อยก่อนเสมอ (ส่วนมากจะแขนซ้ายได้เท่าไหร่เอาแค่นั้นเผื่อแก้กล้ามเนื้อไม่เท่ากัน)
A5: 3 | B5: Single-Arm Close-Grip Lat Pulldown | C5: ความหนัก 7/10 | D5: 3 | E5: 46364 | F5: 46083 | G5: -ไม่ต้องหมุนข้อมือเยอะ ตัวให้นิ่งเป็นพอ -เช่นเดียวกันเริ่มจากฝั่งที่ด้อยก่อนเสมอ สมมุติซ้ายเล่นได้ 10 ขวาก็เล่นแค่ 10 ถึงขวาจะเล่นได้ 12 (เผื่อในระยะยาวจะได้แก้กล้ามเนื้อไม่เท่ากันได้)
A6: 4 Super Sets | B6: Wide-Grip Seated Row | C6: ความหนัก 7/10 | D6: 4 | E6: 12–15 | F6: 0.0625 | G6: -ยกศอกสูงๆขนานกับรำตัวเหมือนตัว T ยืดสุดระยะแล้วดึงให้ความรู้สึกเหมือนศอกจะเลยจากหลังให้ได้ -แนะนำให้ลองดึงโดยใช้หน้าแขนแบบผิดๆก่อน แล้วค่อยถอดความรู้สึกหน้าแขนออกดึงให้ศอกสุดระยะ -กรณีหมดแรงค่อยใช้หน้าแขนหรือโยกตัวเล็กน้อย Cheats 💥ได้เมื่อจำนวนครั้งเกิน 8+
B7: Straight-Arm Pulldown | C7: ความหนัก 7/10 | D7: 3-4 | E7: 7–10 | G7: -แนะนำให้ลองเล่นผิดท่าโดยใช้หลังแขนตัวเองก่อน จากนั้นตัดการใช้หลังแขนออก -หมุนเฟือง ⚙️ เหมือนปีนหน้าผาโดยที่ท่อน Forearm ขาด (ไม่รู้จะเขียนยังไงให้นึกภาพปีนผาแบบแขนด้วน) -ท่องไว้ว่า Straight แขนต้องตรึงไว้ 70-80% ตอนออกแรงเกือบสุดระยะแล้วอยู่ข้างขาอาจเพิ่มเป็น 90% ได้ -ท่านี้ปราบเซียนสอนยากแนะนำให้ถ่ายคลิปตัวเองตอนเล่นเปรียบเทียบกับคนที่ฟรอมส์ดีๆ
A8: 5 Super Sets | B8: Back Extension (Plate,Dumbbell Hold) | C8: ความหนัก 7-8/10 | D8: 3 | E8: 46366 | F8: 0.0625 | G8: -ใครจะถือดัมเบลล์,Plate,Kettel Bell อะไรก็ได้ ถ้าเล่นปกติได้เกิน 15rep+ -เท้าขอให้มั่นคงไม่ลื่นไปมา เข่าล็อคประมาณ 80% ไม่ต้องตรงเป๊ะไม่งั้นจะเอากระดูกเอ็นไปดามเปล่าๆ -ลงให้สุด ขึ้นให้ขนานกับตัวเป็นพอไม่ต้องแอ่นมากๆ (เดียวหลังจะเดาะเอา ) -เบรคแรงต้านให้ได้อย่างเหวี่ยงไปเหวี่ยงมามันดูตลก 🤡
B9: Machine Reverse Fly | C9: ความหนัก 7/10 | E9: 46366 | G9: - นึกถึงท่า Machine Fly วันที่เล่นอก นี้คือมัดคู่ขนาน -ศอกไม่ต้องล็อค 100% 90%ก็พอโอเคแล้ว -แนะนำให้ลองเล่นโดยใช้หลังแขนเต็มที่ก่อนจากนั้นค่อยตัดความรู้สึกการใช้หลังแขน -หมุนเฟืองให้สุดระยะ⚙️ ⬅️ ➡️ระยะมากเท่าไหร่เอาเท่านั้น (ไม่ต้องขยับหลังแขนคงไว้ 90% แบบเดิม)
A10: โปรแกรมเป็นเพียงแนวทาง ปรับ Volume ตามสภาพร่างกายและการฟื้นตัวของตัวเองเป็นหลัก อย่าฝืนซ้อมหากร่างกายส่งสัญญาณว่าพักไม่พอ | H10: License - Baygeta
A11: พักตามความพร้อมของร่างกาย (แนะนำเล่นต่อเนื่อง 4–6 วัน) แล้วนับต่อจากวันที่เล่นล่าสุด | H11: สามารถคัดลอก แก้ไข และแจกจ่ายไฟล์นี้ได้อิสระ ห้ามนำไปขายหรือใช้เพื่อการค้า

Sheet ไหล่ B
A1: No. | B1: Exercise | C1: Weight(Kg) | D1: Sets | E1: Reps | F1: Rest | G1: Tips | H1: Group Muscle
A2: ลำดับ | B2: ชื่อท่า | C2: นน. | D2: เซต | E2: ครั้ง | F2: พัก | G2: แนะนำ | H2: กลุ่มกล้ามเนื้อ
A3: 1 | B3: เลือกท่าใดก็ได้ (รอบหน้าสลับ) 🔄 | C3: =IF(B3="เลือกท่าใดก็ได้ (รอบหน้าสลับ) 🔄","", IF(B3="Dumbbells Shoulder Press", FLOOR( (('(ถามตอบก่อนเล่น) ใส่ข้อมูลเฉพาะ'!D4*0.7) * IF('(ถามตอบก่อนเล่น) ใส่ข้อมูลเฉพาะ'!$D$2="Hard",1, IF('(ถามตอบก่อนเล่น) ใส่ข้อมูลเฉพาะ'!$D$2="Normal",0.9, IF('(ถามตอบก่อนเล่น) ใส่ข้อมูลเฉพาะ'!$D$2="Easy",0.8,1))) )/2 ,5), FLOOR( ('(ถามตอบก่อนเล่น) ใส่ข้อมูลเฉพาะ'!D4*0.7) * IF('(ถามตอบก่อนเล่น) ใส่ข้อมูลเฉพาะ'!$D$2="Hard",1, IF('(ถามตอบก่อนเล่น) ใส่ข้อมูลเฉพาะ'!$D$2="Normal",0.9, IF('(ถามตอบก่อนเล่น) ใส่ข้อมูลเฉพาะ'!$D$2="Easy",0.8,1))) ,5))) | D3: =IF(B3="เลือกท่าใดก็ได้ (รอบหน้าสลับ) 🔄","", IF(B3="กลับบ้าน 🐕", SWITCH('(ถามตอบก่อนเล่น) ใส่ข้อมูลเฉพาะ'!$D$2, "5+","5", "2-4","5", "0-2","4", "4"), SWITCH('(ถามตอบก่อนเล่น) ใส่ข้อมูลเฉพาะ'!$D$2, "5+","4", "2-4","3-4", "0-2","3", "3"))) | E3: =IFS( B3="เลือกท่าใดก็ได้ (รอบหน้าสลับ) 🔄","", B3="Smith Shoulder Press","8-12", B3="Machine Shoulder Press","8-12", B3="Dumbbells Shoulder Press","8-10" ) | F3: =IFS( B3="เลือกท่าใดก็ได้ (รอบหน้าสลับ) 🔄","", B3="Smith Shoulder Press","3"&CHAR(10)&"(ตามฟิล)", B3="Machine Shoulder Press","3"&CHAR(10)&"(ตามฟิล)", B3="Dumbbells Shoulder Press","3"&CHAR(10)&"(ตามฟิล)" ) | G3: =IFS( B3="เลือกท่าใดก็ได้ (รอบหน้าสลับ) 🔄","", B3="Smith Shoulder Press","-จุดเริ่มยิ่งบาร์แตะอกไปเลยยิ่งดีเพราะเริ่มทำงานใช้ไหล่ทันที -แอ่นหน้าอกหลังตรงแต่ไม่ต้องถึงกับขั้นแอ่นหลังอานสุดๆ จะเจ็บเอาได้ -ตอนออกแรงให้ศอกอยู่ใต้มือไว้ออกแรงเหมือนเป็นเส้นตรงขึ้นไป -ลงสุดจนเกือบแตะกับอก (ช่วงแรกถ้าเจ็บไหล่ให้เล่นไต่น้ำหนักเบาๆ)", B3="Machine Shoulder Press","-พยายามหาเครื่องที่ลงได้ลึกจนสุดระยะไหล่ (ถ้าห่างมากเปลี่ยนท่า) -ปรับเบาะรอง 🪑 ให้สูงให้ไหล่ใกล้กับตัวบาร์เหล็กมากที่สุดเมื่อออกแรงจะเริ่มใช้ไหล่ทันที -ศอกไม่ต้องออกข้างแบบสุดๆ เอียงมาหน้าได้เล็กน้อย -ดันขึ้นสุดแล้วล็อคศอกประมาณ 95%+ (ไม่ต้องล็อคสุดให้กร"&"ะดูกรับภาระ)", B3="Dumbbells Shoulder Press","-ใช้เข่า Take ดัมเบลทุกครั้งก่อนเริ่มเล่น -มีสองแบบเล่น ดัมเบลใกล้หูจะได้ไหล่โดยรวมมากกว่า ส่วนถ้าศอกชี้ไปทางข้างหน้าจะโดนไหล่หน้ามากกว่า -ดันขึ้นให้ดัมเบลเข้าหากันเล็กน้อย แต่ไม่ต้องชนกันแรงๆ -ตอนลงให้ลงจนดัมเบลแตะไหล่ (ถ้าลูกเล็กก็ลงตำแหน่งศอกประมาณ 90°"&")" ) | H3: ไหล่
A4: 2 | B4: Lateral Raise Drop set | C4: ความหนัก 8/10 | D4: =IF(B10="กลับบ้าน 🐕", SWITCH('(ถามตอบก่อนเล่น) ใส่ข้อมูลเฉพาะ'!$D$2, "5+","5", "2-4","5", "0-2","4", "4"), SWITCH('(ถามตอบก่อนเล่น) ใส่ข้อมูลเฉพาะ'!$D$2, "5+","3", "2-4","3", "0-2","3", "3")) -> 3 | E4: 10 | F4: 2 | G4: -เซ็ทนึงรวมๆ จะประมาณ 30 Reps จำนวนครั้ง (10,8-12,จนหมด) -ลดน้ำหนักลง 20–30%(น้ำหนัก 35 → 30 → 20) ทุกครั้ง รวมทั้งหมด 3 น้ำหนัก -มือคว่ำเหมือนเทลินน้ำใส่แก้ว อย่าให้ Forearm เลยจอกข้อศอก -ลองล็อคศอกสุดดูแบบยืดตรง 100% จะโดนไหล่มากๆ จากนั้นจะเข้าใจว่าศอกเรารับภาระหนักเล่นระยะยาวคงเจ็บแน่ๆ ให้งอศอกเล็กน้อยพอจะเป็นเหมือนโช๊ครถจะเป็นการใช้กล้ามเนื้อรับแรงกระแทกแทนกระดูก -ไม่ต้องขึ้นเลยระยะไหล่ตอนเล่นให้เอนตัวไปข้างหน้าเล็๋กน้อย -Cheats 💥โดยการแกว่งตัวเล็กน้อยหรือหุบแขนให้
C5: ความหนัก 7/10 | E5: 46364
C6: ความหนัก 6/10 | E6: จนหมด
A7: 3 | B7: Barbell Upright Row | C7: ความหนัก 7/10 | D7: =IF(B10="กลับบ้าน 🐕", SWITCH('(ถามตอบก่อนเล่น) ใส่ข้อมูลเฉพาะ'!$D$2, "5+","5", "2-4","5", "0-2","4", "4"), SWITCH('(ถามตอบก่อนเล่น) ใส่ข้อมูลเฉพาะ'!$D$2, "5+","4", "2-4","3-4", "0-2","3", "3")) -> 3 | E7: 10–15 | F7: 0.0625 | G7: -ส่วนตัวจับระยะกว้างกว่าระยะไหล่เล็กน้อย เช่นเดียวกับ Lateral Raise (ขึ้นอยู่กับความยาวแขนแต่ละคน) -แนะนำให้ลองจับจนมุมที่รู้สึกไหล่ทำงานสุดๆ โดยล้ำหนักหนักแบบวอรม์ 20rep ลองความห่างหาไปเรื่อยๆจนเจอ -ท่านี้เล่นยังไง tap ก็ทำงาน (แต่อย่าเอามาใช้หลักแทนไหล่) -โยกตัวได้เล็กน้อยตอน Cheats 💥 8+rep
A8: 4 | B8: เลือกท่าใดก็ได้ (รอบหน้าสลับ) 🔄 | C8: =IFS( B8="เลือกท่าใดก็ได้ (รอบหน้าสลับ) 🔄","", B8="Front Raise -Wall Support","ความหนัก 6-7/10", B8="Front Raise","ความหนัก 7/10", B8="Single Arm Cable Front Raise","ความหนัก 6-7/10", B8="Straight bar Cable Front Raise","ความหนัก 7-8/10" ) | D8: =IF(B8="เลือกท่าใดก็ได้ (รอบหน้าสลับ) 🔄","", IF(B10="กลับบ้าน 🐕", SWITCH('(ถามตอบก่อนเล่น) ใส่ข้อมูลเฉพาะ'!$D$2, "5+","5", "2-4","5", "0-2","4", "4"), SWITCH('(ถามตอบก่อนเล่น) ใส่ข้อมูลเฉพาะ'!$D$2, "5+","4", "2-4","3-4", "0-2","3", "3"))) | E8: =IFS( B8="เลือกท่าใดก็ได้ (รอบหน้าสลับ) 🔄","", B8="Front Raise -Wall Support","12-15", B8="Front Raise","10-12", B8="Single Arm Cable Front Raise","12-15", B8="Straight bar Cable Front Raise","8-10" ) | F8: =IF(B8="เลือกท่าใดก็ได้ (รอบหน้าสลับ) 🔄","", "1") | G8: =IFS( B8="เลือกท่าใดก็ได้ (รอบหน้าสลับ) 🔄","", B8="Front Raise -Wall Support","-เหมือน Front Raise ทุกอย่างให้นำหลังชิดกับกำแพงเผื่อให้ตัวไม่โยก -ศอกตรึงประมาณ 90-95% -ตอนออกแรงให้นึกถึงหมุนเฟืองขึ้นมา⚙️ยกได้จนถึงระยะคิ้วตัวเอง -สะบักกับก้น 4 จุดแตะกับกำแพงเหมือขาเก้าอี้ 🪑 -ถ้าเกิน 9+Reps แล้วไม่ไหว สามารถออกจากกำแพงแล้ว Cheats 💥ไ"&"ด้จนหมด", B8="Front Raise","-ศอกตรึงประมาณ 90-95% -ตอนออกแรงให้นึกถึงหมุนเฟืองขึ้นมา⚙️ยกได้จนถึงระยะคิ้วตัวเอง -ถ้าเกิน 10+ Reps แล้วไม่ไหว Cheats 💥โยกตัวช่วยเล็กน้อยได้", B8="Single Arm Cable Front Raise","-เซ็ท cable ต่ำสุด -ศอกล็อคประมาณ 90-95% -ดึงขึ้นประมาณ ระดับสายตาหรือคิ้ว -ตอนลงให้ คุมแรงต้าน อย่าให้แผ่นเหล็กกระทบกัน -ถ้าเกิน 10 Reps แล้วไม่ไหว สามารถ Cheats 💥 เล็กน้อยได้เพื่อจบเซ็ต (ใช้อีกมือช่วย) -ข้อดีของการเล่นที่ละข้างคือจะ รู้หรือแก้สาเหตุกล้"&"ามเนื้อเรา Balance หรือไม่", B8="Straight bar Cable Front Raise","-เซ็ท cable ต่ำสุด -ศอกล็อคประมาณ 90-95% -ขึ้นประมาณ ระดับคิ้ว อย่าแกว่งตัวเหมือนที่ขุดน้ำมัน🛢️ -ถ้าเกิน 10 Reps แล้วไม่ไหว สามารถ Cheats 💥 เล็กน้อยได้เพื่อจบเซ็ต (โยกตัวเบาๆเอา) -สายซิ่งรอบจะไวกว่า single arm" ) | H8: ไหล่+ท้อง
A9: Super Sets | B9: Roman Chair Side Crunch | C9: ความหนัก 7/10 | D9: =IF(B10="กลับบ้าน 🐕", SWITCH('(ถามตอบก่อนเล่น) ใส่ข้อมูลเฉพาะ'!$D$2, "5+","5", "2-4","5", "0-2","4", "4"), SWITCH('(ถามตอบก่อนเล่น) ใส่ข้อมูลเฉพาะ'!$D$2, "5+","4", "2-4","3-4", "0-2","3", "3")) -> 3 | E9: 12-20 | F9: 1 | G9: -ปรับเบาะถึงช่วงเอวข้อพับ -หลังตรงแบบเคารพธงชาติ ไม่งอ และ ไม่แอ่น -พยายามไม่ก้มหรือเงย การก้มทำให้เราหลังค่อมเป็นหอยทากอัติโนมัติ เช่นเดียวกับเงยก็หลังแอ่นเป็นนกนางแอ่น -เบาไปเกิน 20 Reps+เอา Kettle Bell หรือดัมเบลมาถือ -อย่าแกว่งไปมาไม่ค่อยได้อะไรเท่าไหร่ ยกเว้น Cheats💥 10+rep
A10: 5 | B10: เลือกท่าใดก็ได้ (รอบหน้าสลับ) 🔄 | C10: =IFS( B10="เลือกท่าใดก็ได้ (รอบหน้าสลับ) 🔄","", B10="Machine Reverse Fly","ความหนัก 7-8/10", B10="Cable Reverse Fly","ความหนัก 7/10", B10="Dumbbells Reverse Fly","ความหนัก 6-7/10", B10="กลับบ้าน 🐕","ความหนัก 1/10" ) | D10: =IF(B10="เลือกท่าใดก็ได้ (รอบหน้าสลับ) 🔄","", IF(B10="กลับบ้าน 🐕", SWITCH('(ถามตอบก่อนเล่น) ใส่ข้อมูลเฉพาะ'!$D$2, "5+","5", "2-4","5", "0-2","4", "4"), SWITCH('(ถามตอบก่อนเล่น) ใส่ข้อมูลเฉพาะ'!$D$2, "5+","4", "2-4","3-4", "0-2","3", "3"))) | E10: =IFS( B10="เลือกท่าใดก็ได้ (รอบหน้าสลับ) 🔄","", B10="Machine Reverse Fly","10-12", B10="Cable Reverse Fly","12-15", B10="Dumbbells Reverse Fly","12-15", B10="กลับบ้าน 🐕","0" ) | F10: =IF(OR(B10="เลือกท่าใดก็ได้ (รอบหน้าสลับ) 🔄",B10="กลับบ้าน 🐕"),,1) | G10: =IFS( B10="เลือกท่าใดก็ได้ (รอบหน้าสลับ) 🔄","", B10="Machine Reverse Fly","-ปรับเบาะให้ 3 ระดับ ขนานกับไหล่/ต่ำกว่า/สูงกว่า สลับรอบกันเล่น -ศอกงอเล็กน้อยเพื่อไม่ให้กระดูกดาม -ออกแรงให้รู้สึกที่ไหล่หลังสุดระยะ -ด้านลึก 2 วิ อย่าปล่อยให้เหล็กกระทบกัน", B10="Cable Reverse Fly","-ยืนให้ลำตัวนิ่ง อกเปิด หลังตรง -หมุนเฟือง⚙️ไหล่ไปด้านหลังเหมือนพยายามบีบสะบักเข้าหากัน -อย่าปล่อยให้น้ำหนักเหล็กเกืดเสียงกระทบกัน (ไม่งั้นแรงต้านจะหาย) ", B10="Dumbbells Reverse Fly","-เอนตัวประมาณ 45° -ศอกงอเล็กน้อย -ออกแรงให้รู้สึกที่ไหล่หลังสุดระยะ -ถ้าเกิน 10 Reps แล้วไม่ไหว สามารถ Cheats 💥 เล็กน้อยได้", B10="กลับบ้าน 🐕","🥀🥀🥀🥀🥀🥀" )
